Workbook

Sheet Cover
A1: Financial Model - Colgate Palmolive (unsolved template)
A3: Prepared by Dheeraj Vaidya, CFA, FRM
A4: dheeraj@wallstreetmojo.com
A6: For step by step instruction, please visit - https://www.wallstreetmojo.com/financial-modeling-in-excel/
A8: Table of Contents
B9: Income Statements
B10: Balance Sheet
B11: Cash Flows
B12: Depreciation Forecast Sheet
B13: Amortization Forecast Sheet
B14: Working Capital Forecast
B15: Other Long Term Forecast
B16: Shareholder's Equity Forecast
B17: Shares Outstanding Forecast
B18: Debt Forecast
A20: visit - www.wallstreetmojo.com

Sheet IS
A1: Colgate-Palmolive Company
A3: Income Statement (Consolidated)
B5: ($ in Million Except Per Share Amounts) | C5: 42735 | D5: =EOMONTH(C5,12) -> 43100 | E5: =EOMONTH(D5,12) -> 43465 | F5: =EOMONTH(E5,12) -> 43830 | G5: =EOMONTH(F5,12) -> 44196 | H5: =EOMONTH(G5,12) -> 44561 | I5: =EOMONTH(H5,12) -> 44926 | J5: =EOMONTH(I5,12) -> 45291 | K5: =EOMONTH(J5,12) -> 45657 | L5: =EOMONTH(K5,12) -> 46022
B6: Net sales | C6: 15195 | D6: 15454 | E6: 15544 | F6: 15693 | G6: 16471 | H6: =H106 -> 17222.39 | I6: =I106 -> 18035.824 | J6: =J106 -> 18916.992 | K6: =K106 -> 19872.117 | L6: =L106 -> 20908.012
B7: Cost of sales | C7: 6072 | D7: 6174 | E7: 6313 | F7: 6368 | G7: 6454 | H7: =H6*H32 -> 6888.956 | I7: =I6*I32 -> 7214.3297 | J7: =J6*J32 -> 7566.7967 | K7: =K6*K32 -> 7948.8467 | L7: =L6*L32 -> 8363.2047
B8: Gross profit | C8: =C6-C7 -> 9123 | D8: =D6-D7 -> 9280 | E8: =E6-E7 -> 9231 | F8: =F6-F7 -> 9325 | G8: =G6-G7 -> 10017 | H8: =H6-H7 -> 10333.434 | I8: =I6-I7 -> 10821.495 | J8: =J6-J7 -> 11350.195 | ... L8: =L6-L7 -> 12544.807
B10: Selling, general and administrative expenses | C10: 5143 | D10: 5400 | E10: 5389 | F10: 5575 | G10: 6019 | H10: =H6*H35 -> 6200.0604 | I10: =I6*I35 -> 6492.8967 | J10: =J6*J35 -> 6810.117 | K10: =K6*K35 -> 7153.9621 | L10: =L6*L35 -> 7526.8842
B11: Other (income) expense, net | C11: 25 | D11: 173 | E11: 148 | F11: 196 | G11: 113 | H11: =H6*H36 -> 172.2239 | I11: =I6*I36 -> 180.35824 | J11: =J6*J36 -> 189.16992 | K11: =K6*K36 -> 198.72117 | L11: =L6*L36 -> 209.08012
B12: EBIT | C12: =C8-C10-C11 -> 3955 | D12: =D8-D10-D11 -> 3707 | E12: =E8-E10-E11 -> 3694 | F12: =F8-F10-F11 -> 3554 | G12: =G8-G10-G11 -> 3885 | H12: =H8-(H10+H11) -> 3961.1497 | I12: =I8-(I10+I11) -> 4148.2396 | J12: =J8-(J10+J11) -> 4350.9081 | K12: =K8-(K10+K11) -> 4570.5869 | L12: =L8-(L10+L11) -> 4808.8427
B13: Non-service related postretirement costs | C13: 118 | D13: 118 | E13: 87 | F13: 108 | G13: 74 | H13: =H6*H38 -> 68.88956 | I13: =I6*I38 -> 72.143297 | J13: =J6*J38 -> 75.667967 | K13: =K6*K38 -> 79.488467 | L13: =L6*L38 -> 83.632047
B14: Interest expense, net | C14: 99 | D14: 102 | E14: 143 | F14: 145 | G14: 164 | H14: =Debt!H42-Debt!H47 -> 157.58851 | I14: =Debt!I42-Debt!I47 -> 153.40183 | J14: =Debt!J42-Debt!J47 -> 150.65458 | K14: =Debt!K42-Debt!K47 -> 146.72035 | L14: =Debt!L42-Debt!L47 -> 148.75672
B16: EBT | C16: =C12-C14-C13 -> 3738 | D16: =D12-D14-D13 -> 3487 | E16: =E12-E14-E13 -> 3464 | F16: =F12-F14-F13 -> 3301 | G16: =G12-G14-G13 -> 3647 | H16: =H12-H14-H13 -> 3734.6716 | I16: =I12-I14-I13 -> 3922.6945 | J16: =J12-J14-J13 -> 4124.5855 | ... L16: =L12-L14-L13 -> 4576.4539
B17: Provision for income taxes | C17: 1152 | D17: 1313 | E17: 906 | F17: 774 | G17: 787 | H17: =H16*H47 -> 821.62776 | I17: =I16*I47 -> 862.99278 | J17: =J16*J47 -> 907.40882 | K17: =K16*K47 -> 955.76317 | L17: =L16*L47 -> 1006.8199
B18: Net income including noncontrolling interests | C18: =C16-C17 -> 2586 | D18: =D16-D17 -> 2174 | E18: =E16-E17 -> 2558 | F18: =F16-F17 -> 2527 | G18: =G16-G17 -> 2860 | H18: =H16-H17 -> 2913.0439 | I18: =I16-I17 -> 3059.7017 | J18: =J16-J17 -> 3217.1767 | ... L18: =L16-L17 -> 3569.6341
B19: Less: Net income attributable to noncontrolling interests | C19: 145 | D19: 150 | E19: 158 | F19: 160 | G19: 165 | H19: =H18*H44 -> 174.78263 | I19: =I18*I44 -> 183.5821 | J19: =J18*J44 -> 193.0306 | K19: =K18*K44 -> 203.31689 | L19: =L18*L44 -> 214.17804
B20: Net income attributable to Colgate-Palmolive Company | C20: =C18-C19 -> 2441 | D20: =D18-D19 -> 2024 | E20: =E18-E19 -> 2400 | F20: =F18-F19 -> 2367 | G20: =G18-G19 -> 2695 | H20: =H18-H19 -> 2738.2612 | I20: =I18-I19 -> 2876.1196 | J20: =J18-J19 -> 3024.1461 | ... L20: =L18-L19 -> 3355.456
B21: Earnings per common share, basic | C21: 2.74 | D21: 2.3 | E21: 2.76 | F21: 2.76 | G21: 3.15 | H21: =H20/H24 -> 3.254226 | I21: =I20/I24 -> 3.4654223 | J21: =J20/J24 -> 3.6949774 | K21: =K20/K24 -> 3.9473409 | L21: =L20/L24 -> 4.2183234
B22: Earnings per common share, diluted | C22: 2.72 | D22: 2.28 | E22: 2.75 | F22: 2.75 | G22: 3.14 | H22: =H20/H25 -> 3.243113 | I22: =I20/I25 -> 3.4534247 | J22: =J20/J25 -> 3.682006 | K22: =K20/K25 -> 3.9332867 | L22: =L20/L25 -> 4.2030881
B24: Basic Weighted Average Shares | C24: 891.8 | D24: 881.1 | E24: 870.6 | F24: 859.1 | G24: 856.8 | H24: ='Shares Outstanding '!H11 -> 841.44779 | I24: ='Shares Outstanding '!I11 -> 829.94779 | J24: ='Shares Outstanding '!J11 -> 818.44779 | K24: ='Shares Outstanding '!K11 -> 806.94779 | L24: ='Shares Outstanding '!L11 -> 795.44779
B25: Diluted Weighted Average Shares | C25: =C24+6.6 -> 898.4 | D25: =D24+6 -> 887.1 | E25: =E24+2.4 -> 873 | F25: =F24+2 -> 861.1 | G25: =G24+2.5 -> 859.3 | H25: ='Shares Outstanding '!H13 -> 844.33112 | I25: ='Shares Outstanding '!I13 -> 832.83112 | J25: ='Shares Outstanding '!J13 -> 821.33112 | K25: ='Shares Outstanding '!K13 -> 809.83112 | L25: ='Shares Outstanding '!L13 -> 798.33112
B27: EBITDA
A30: Vertical Analysis | C30: =C5 -> 42735 | D30: =D5 -> 43100 | E30: =E5 -> 43465 | F30: =F5 -> 43830 | G30: =G5 -> 44196 | H30: =H5 -> 44561 | I30: =I5 -> 44926 | J30: =J5 -> 45291 | ... L30: =L5 -> 46022
B31: Net sales | C31: =C6/C$6 -> 1 | D31: =D6/D$6 -> 1 | E31: =E6/E$6 -> 1 | F31: =F6/F$6 -> 1 | G31: =G6/G$6 -> 1 | H31: =H6/H$6 -> 1 | I31: =I6/I$6 -> 1 | J31: =J6/J$6 -> 1 | ... L31: =L6/L$6 -> 1
B32: Cost of sales | C32: =C7/C$6 -> 0.39960513 | D32: =D7/D$6 -> 0.39950822 | E32: =E7/E$6 -> 0.40613742 | F32: =F7/F$6 -> 0.40578602 | G32: =G7/G$6 -> 0.3918402 | H32: 0.4 | I32: 0.4 | J32: 0.4 | K32: 0.4 | L32: 0.4
B33: Gross profit Margin | C33: =C8/C$6 -> 0.60039487 | D33: =D8/D$6 -> 0.60049178 | E33: =E8/E$6 -> 0.59386258 | F33: =F8/F$6 -> 0.59421398 | G33: =G8/G$6 -> 0.6081598 | H33: =H31-H32 -> 0.6 | I33: =I31-I32 -> 0.6 | J33: =J31-J32 -> 0.6 | K33: =K31-K32 -> 0.6 | L33: =L31-L32 -> 0.6
B35: Selling, general and administrative expenses | C35: =C10/C$6 -> 0.3384666 | D35: =D10/D$6 -> 0.3494241 | E35: =E10/E$6 -> 0.34669326 | F35: =F10/F$6 -> 0.35525393 | G35: =G10/G$6 -> 0.36543015 | H35: 0.36 | I35: 0.36 | J35: 0.36 | K35: 0.36 | L35: 0.36
B36: Other (income) expense, net | C36: =C11/C$6 -> 0.0016452781 | D36: =D11/D$6 -> 0.011194513 | E36: =E11/E$6 -> 0.0095213587 | F36: =F11/F$6 -> 0.012489645 | G36: =G11/G$6 -> 0.0068605428 | H36: 0.01 | I36: 0.01 | J36: 0.01 | K36: 0.01 | L36: 0.01
B37: Operating profit Margin (EBIT Margin) | C37: =C12/C$6 -> 0.26028299 | D37: =D12/D$6 -> 0.23987317 | E37: =E12/E$6 -> 0.23764797 | F37: =F12/F$6 -> 0.2264704 | G37: =G12/G$6 -> 0.2358691 | H37: 0.23 | I37: 0.23 | J37: 0.23 | K37: 0.23 | L37: 0.23
B38: Non-service related postretirement costs | E38: =E13/E$6 -> 0.0055970149 | F38: =F13/F$6 -> 0.0068820493 | G38: =G13/G$6 -> 0.0044927448 | H38: 0.004 | I38: 0.004 | J38: 0.004 | K38: 0.004 | L38: 0.004
B39: Interest expense, net | C39: =C14/C$6 -> 0.0065153011 | D39: =D14/D$6 -> 0.0066002329 | E39: =E14/E$6 -> 0.0091996912 | F39: =F14/F$6 -> 0.0092397884 | G39: =G14/G$6 -> 0.0099568939
B41: Income before income taxes (EBT Margin) | C41: =C16/C$6 -> 0.24600197 | D41: =D16/D$6 -> 0.22563738 | E41: =E16/E$6 -> 0.22285126 | F41: =F16/F$6 -> 0.21034856 | G41: =G16/G$6 -> 0.22141946 | H41: =H16/H$6 -> 0.21684979 | I41: =I16/I$6 -> 0.2174946 | J41: =J16/J$6 -> 0.21803602 | ... L41: =L16/L$6 -> 0.21888518
B42: Provision for income taxes | C42: =C17/C$6 -> 0.075814413 | D42: =D17/D$6 -> 0.084961822 | E42: =E17/E$6 -> 0.058286155 | F42: =F17/F$6 -> 0.049321353 | G42: =G17/G$6 -> 0.047780948 | H42: =H17/H$6 -> 0.047706953 | I42: =I17/I$6 -> 0.047848813 | J42: =J17/J$6 -> 0.047967924 | ... L42: =L17/L$6 -> 0.04815474
B43: Net income Margin including noncontrolling interests | C43: =C18/C$6 -> 0.17018756 | D43: =D18/D$6 -> 0.14067555 | E43: =E18/E$6 -> 0.16456511 | F43: =F18/F$6 -> 0.16102721 | G43: =G18/G$6 -> 0.17363852 | H43: =H18/H$6 -> 0.16914283 | I43: =I18/I$6 -> 0.16964579 | J43: =J18/J$6 -> 0.17006809 | ... L43: =L18/L$6 -> 0.17073044
B44: Less: Net income attributable to noncontrolling interests (% of Net Income) | C44: =C19/C$18 -> 0.056071152 | D44: =D19/D$18 -> 0.06899724 | E44: =E19/E$18 -> 0.061767005 | F44: =F19/F$18 -> 0.063316185 | G44: =G19/G$18 -> 0.057692308 | H44: 0.06 | I44: 0.06 | J44: 0.06 | K44: 0.06 | L44: 0.06
B45: Net income Margin | C45: =C20/C$6 -> 0.16064495 | D45: =D20/D$6 -> 0.13096933 | E45: =E20/E$6 -> 0.15440041 | F45: =F20/F$6 -> 0.15083158 | G45: =G20/G$6 -> 0.16362091 | H45: 0.159 | I45: 0.159 | J45: 0.159 | K45: 0.159 | L45: 0.159
B47: Effective Tax Rates | C47: =C17/C16 -> 0.3081862 | D47: =D17/D16 -> 0.37654144 | E47: =E17/E16 -> 0.26154734 | F47: =F17/F16 -> 0.2344744 | G47: =G17/G16 -> 0.2157938 | H47: 0.22 | I47: 0.22 | J47: 0.22 | K47: 0.22 | L47: 0.22
A50: Horizontal Analysis | C50: =C30 -> 42735 | D50: =D30 -> 43100 | E50: =E30 -> 43465 | F50: =F30 -> 43830 | G50: =G30 -> 44196 | H50: =H30 -> 44561 | I50: =I30 -> 44926 | J50: =J30 -> 45291 | ... L50: =L30 -> 46022
B51: Net sales | D51: =D6/C6-1 -> 0.017045081 | E51: =E6/D6-1 -> 0.005823735 | F51: =F6/E6-1 -> 0.0095856922 | G51: =G6/F6-1 -> 0.049576244 | H51: =H6/G6-1 -> 0.045618967 | I51: =I6/H6-1 -> 0.047231209 | J51: =J6/I6-1 -> 0.048856506 | K51: =K6/J6-1 -> 0.050490332 | L51: =L6/K6-1 -> 0.052128055
B52: Cost of sales | D52: =D7/C7-1 -> 0.016798419 | E52: =E7/D7-1 -> 0.022513767 | F52: =F7/E7-1 -> 0.0087121812 | G52: =G7/F7-1 -> 0.013505025 | H52: =H7/G7-1 -> 0.067393244 | I52: =I7/H7-1 -> 0.047231209 | J52: =J7/I7-1 -> 0.048856506 | K52: =K7/J7-1 -> 0.050490332 | L52: =L7/K7-1 -> 0.052128055
B53: Gross profit | D53: =D8/C8-1 -> 0.017209251 | E53: =E8/D8-1 -> -0.0052801724 | F53: =F8/E8-1 -> 0.010183079 | G53: =G8/F8-1 -> 0.074209115 | H53: =H8/G8-1 -> 0.031589698 | I53: =I8/H8-1 -> 0.047231209 | J53: =J8/I8-1 -> 0.048856506 | K53: =K8/J8-1 -> 0.050490332 | L53: =L8/K8-1 -> 0.052128055
...

Sheet BS
A1: =IS!A1 -> Colgate-Palmolive Company
A3: Consolidated Balance Sheets
C5: =IS!C5 -> 42735 | D5: =IS!D5 -> 43100 | E5: =IS!E5 -> 43465 | F5: =IS!F5 -> 43830 | G5: =IS!G5 -> 44196 | H5: =IS!H5 -> 44561 | I5: =IS!I5 -> 44926 | J5: =IS!J5 -> 45291 | ... L5: =IS!L5 -> 46022
B6: Assets
B7: Current Assets
B8: Cash and cash equivalents | C8: 1315 | D8: 1535 | E8: 726 | F8: 883 | G8: 888 | H8: =CF!H49 -> 500 | I8: =CF!I49 -> 500 | J8: =CF!J49 -> 500 | K8: =CF!K49 -> 651.27502 | L8: =CF!L49 -> 651.27502
B9: Receivables | C9: 1411 | D9: 1480 | E9: 1400 | F9: 1440 | G9: 1264 | H9: ='Working Capital'!H10 -> 1567.0778 | I9: ='Working Capital'!I10 -> 1397.7152 | J9: ='Working Capital'!J10 -> 1711.9272 | K9: ='Working Capital'!K10 -> 1554.7221 | L9: ='Working Capital'!L10 -> 1882.2113
B10: Inventories | C10: 1171 | D10: 1221 | E10: 1250 | F10: 1400 | G10: 1673 | H10: ='Working Capital'!H11 -> 1535.5548 | I10: ='Working Capital'!I11 -> 1824.5439 | J10: ='Working Capital'!J11 -> 1699.7175 | K10: ='Working Capital'!K11 -> 2002.4851 | L10: ='Working Capital'!L11 -> 1892.7062
B11: Other current assets | C11: 441 | D11: 403 | E11: 417 | F11: 456 | G11: 513 | H11: ='Working Capital'!H12 -> 533.89409 | I11: ='Working Capital'!I12 -> 559.11055 | J11: ='Working Capital'!J12 -> 586.42674 | K11: ='Working Capital'!K12 -> 616.03562 | L11: ='Working Capital'!L12 -> 648.14836
B12: Total current assets | C12: =SUM(C8:C11) -> 4338 | D12: =SUM(D8:D11) -> 4639 | E12: =SUM(E8:E11) -> 3793 | F12: =SUM(F8:F11) -> 4179 | G12: =SUM(G8:G11) -> 4338 | H12: =SUM(H8:H11) -> 4136.5267 | I12: =SUM(I8:I11) -> 4281.3697 | J12: =SUM(J8:J11) -> 4498.0715 | ... L12: =SUM(L8:L11) -> 5074.3409
B14: Property, plant and equipment, net | C14: 3840 | D14: 4072 | E14: 3881 | F14: 3750 | G14: 3716 | H14: ='Dep Capex '!H13 -> 3713.064 | I14: ='Dep Capex '!I13 -> 3704.0286 | J14: ='Dep Capex '!J13 -> 3689.4598 | K14: ='Dep Capex '!K13 -> 3669.9877 | L14: ='Dep Capex '!L13 -> 3646.3129
B15: Goodwill, net | C15: 2107 | D15: 2218 | E15: 2530 | F15: 3508 | G15: 3824 | H15: ='Other Long Term Asset Liability'!H8 -> 3824 | I15: ='Other Long Term Asset Liability'!I8 -> 3824 | J15: ='Other Long Term Asset Liability'!J8 -> 3824 | K15: ='Other Long Term Asset Liability'!K8 -> 3824 | L15: ='Other Long Term Asset Liability'!L8 -> 3824
B16: Other intangible assets, net | C16: 1313 | D16: 1341 | E16: 1637 | F16: 2667 | G16: 2894 | H16: ='Amort Intangible'!H13 -> 3155.4478 | I16: ='Amort Intangible'!I13 -> 3433.1643 | J16: ='Amort Intangible'!J13 -> 3728.5041 | K16: ='Amort Intangible'!K13 -> 4042.9465 | L16: ='Amort Intangible'!L13 -> 4378.1067
B17: Deferred income taxes | C17: 301 | D17: 188 | E17: 152 | F17: 177 | G17: 291 | H17: ='Other Long Term Asset Liability'!H9 -> 291 | I17: ='Other Long Term Asset Liability'!I9 -> 291 | J17: ='Other Long Term Asset Liability'!J9 -> 291 | K17: ='Other Long Term Asset Liability'!K9 -> 291 | L17: ='Other Long Term Asset Liability'!L9 -> 291
B18: Other assets | C18: 224 | D18: 218 | E18: 168 | F18: 753 | G18: 857 | H18: ='Other Long Term Asset Liability'!H10 -> 857 | I18: ='Other Long Term Asset Liability'!I10 -> 857 | J18: ='Other Long Term Asset Liability'!J10 -> 857 | K18: ='Other Long Term Asset Liability'!K10 -> 857 | L18: ='Other Long Term Asset Liability'!L10 -> 857
B19: Total assets | C19: =SUM(C12:C18) -> 12123 | D19: =SUM(D12:D18) -> 12676 | E19: =SUM(E12:E18) -> 12161 | F19: =SUM(F12:F18) -> 15034 | G19: =SUM(G12:G18) -> 15920 | H19: =SUM(H12:H18) -> 15977.039 | I19: =SUM(I12:I18) -> 16390.563 | J19: =SUM(J12:J18) -> 16888.035 | ... L19: =SUM(L12:L18) -> 18070.76
B21: Liabilities and Shareholders' Equity
B22: Current Liabilities
B23: Notes and loans payable | C23: 13 | D23: 11 | E23: 12 | F23: 260 | G23: 258 | H23: =G23 -> 258 | I23: =H23 -> 258 | J23: =I23 -> 258 | K23: =J23 -> 258 | L23: =K23 -> 258
B24: Current portion of long-term debt | F24: 254 | G24: 9 | H24: =Debt!H29 -> 413 | I24: =Debt!I29 -> 896 | J24: =Debt!J29 -> 498 | K24: =Debt!K29 -> 130 | L24: =Debt!L29 -> 100
B25: Accounts payable | C25: 1124 | D25: 1212 | E25: 1222 | F25: 1237 | G25: 1393 | H25: ='Working Capital'!H15 -> 1196.6206 | I25: ='Working Capital'!I15 -> 1681.3647 | J25: ='Working Capital'!J15 -> 1173.0897 | K25: ='Working Capital'!K15 -> 1991.9131 | L25: ='Working Capital'!L15 -> 1173.7845
B26: Accrued income taxes | C26: 441 | D26: 354 | E26: 411 | F26: 370 | G26: 403 | H26: ='Working Capital'!H16 -> 427.11527 | I26: ='Working Capital'!I16 -> 447.28844 | J26: ='Working Capital'!J16 -> 469.14139 | K26: ='Working Capital'!K16 -> 492.8285 | L26: ='Working Capital'!L16 -> 518.51869
B27: Other accruals | C27: 1727 | D27: 1831 | E27: 1696 | F27: 1917 | G27: 2341 | H27: ='Working Capital'!H17 -> 2066.6868 | I27: ='Working Capital'!I17 -> 2164.2989 | J27: ='Working Capital'!J17 -> 2270.039 | K27: ='Working Capital'!K17 -> 2384.654 | L27: ='Working Capital'!L17 -> 2508.9614
B28: Total current liabilities | C28: =SUM(C23:C27) -> 3305 | D28: =SUM(D23:D27) -> 3408 | E28: =SUM(E23:E27) -> 3341 | F28: =SUM(F23:F27) -> 4038 | G28: =SUM(G23:G27) -> 4404 | H28: =SUM(H23:H27) -> 4361.4227 | I28: =SUM(I23:I27) -> 5446.9521 | J28: =SUM(J23:J27) -> 4668.2701 | ... L28: =SUM(L23:L27) -> 4559.2646
B30: Revolver | H30: =Debt!H20 -> 860.46853 | I30: =Debt!I20 -> 843.64221 | J30: =Debt!J20 -> 2414.0358 | K30: =Debt!K20 -> 2414.0358 | L30: =Debt!L20 -> 3657.0431
B32: Long-term debt | C32: 6520 | D32: 6566 | E32: 6354 | F32: 7333 | G32: 7334 | H32: =Debt!H28 -> 6299 | I32: =Debt!I28 -> 5403 | J32: =Debt!J28 -> 4905 | K32: =Debt!K28 -> 4775 | L32: =Debt!L28 -> 4675
B33: Deferred income taxes | C33: 246 | D33: 204 | E33: 235 | F33: 507 | G33: 426 | H33: ='Other Long Term Asset Liability'!H13 -> 426 | I33: ='Other Long Term Asset Liability'!I13 -> 426 | J33: ='Other Long Term Asset Liability'!J13 -> 426 | K33: ='Other Long Term Asset Liability'!K13 -> 426 | L33: ='Other Long Term Asset Liability'!L13 -> 426
B34: Other liabilities | C34: 2035 | D34: 2255 | E34: 2034 | F34: 2598 | G34: 2655 | H34: ='Other Long Term Asset Liability'!H14 -> 2655 | I34: ='Other Long Term Asset Liability'!I14 -> 2655 | J34: ='Other Long Term Asset Liability'!J14 -> 2655 | K34: ='Other Long Term Asset Liability'!K14 -> 2655 | L34: ='Other Long Term Asset Liability'!L14 -> 2655
B35: Total liabilities | C35: =SUM(C28:C34) -> 12106 | D35: =SUM(D28:D34) -> 12433 | E35: =SUM(E28:E34) -> 11964 | F35: =SUM(F28:F34) -> 14476 | G35: =SUM(G28:G34) -> 14819 | H35: =SUM(H28:H34) -> 14601.891 | I35: =SUM(I28:I34) -> 14774.594 | J35: =SUM(J28:J34) -> 15068.306 | ... L35: =SUM(L28:L34) -> 15972.308
B36: Commitments and contingent liabilities | C36: - | D36: - | E36: - | F36: - | G36: -
B37: Shareholders' Equity
B38: Common stock | C38: 1466 | D38: 1466 | E38: 1466 | F38: 1466 | G38: 1466
B39: Additional paid-in capital | C39: 1691 | D39: 1984 | E39: 2204 | F39: 2488 | G39: 2969
B40: Retained earnings | C40: 19922 | D40: 20531 | E40: 21615 | F40: 22501 | G40: 23699
B41: Accumulated other comprehensive income (loss) | C41: -4180 | D41: -3855 | E41: -4188 | F41: -4273 | G41: -4345
B42: Unearned compensation | C42: -7 | D42: -5 | E42: -3 | F42: -2 | G42: -1
B43: Treasury stock, at cost | C43: -19135 | D43: -20181 | E43: -21196 | F43: -22063 | G43: -23045
B44: Total shareholders' equity | C44: =SUM(C38:C43) -> -243 | D44: =SUM(D38:D43) -> -60 | E44: =SUM(E38:E43) -> -102 | F44: =SUM(F38:F43) -> 117 | G44: =SUM(G38:G43) -> 743 | H44: ='Shareholders Equity'!H11 -> 842.36473 | I44: ='Shareholders Equity'!I11 -> 899.60363 | J44: ='Shareholders Equity'!J11 -> 910.3343 | K44: ='Shareholders Equity'!K11 -> 869.30839 | L44: ='Shareholders Equity'!L11 -> 771.56256
B45: Noncontrolling interests | C45: 260 | D45: 303 | E45: 299 | F45: 441 | G45: 358 | H45: =G45+IS!H19 -> 532.78263 | I45: =H45+IS!I19 -> 716.36473 | J45: =I45+IS!J19 -> 909.39534 | K45: =J45+IS!K19 -> 1112.7122 | L45: =K45+IS!L19 -> 1326.8903
B46: Total shareholders' equity | C46: =SUM(C44:C45) -> 17 | D46: =SUM(D44:D45) -> 243 | E46: =SUM(E44:E45) -> 197 | F46: =SUM(F44:F45) -> 558 | G46: =SUM(G44:G45) -> 1101 | H46: =SUM(H44:H45) -> 1375.1474 | I46: =SUM(I44:I45) -> 1615.9684 | J46: =SUM(J44:J45) -> 1819.7296 | ... L46: =SUM(L44:L45) -> 2098.4528
...

Sheet CF
A1: =IS!A1 -> Colgate-Palmolive Company
A3: Consolidated Cash Flows
C5: =BS!C5 -> 42735 | D5: =BS!D5 -> 43100 | E5: =BS!E5 -> 43465 | F5: =BS!F5 -> 43830 | G5: =BS!G5 -> 44196 | H5: =BS!H5 -> 44561 | I5: =BS!I5 -> 44926 | J5: =BS!J5 -> 45291 | ... L5: =BS!L5 -> 46022
B6: Operating Activities
B7: Net income including noncontrolling interests | E7: 2558 | F7: 2527 | G7: 2860 | H7: =IS!H18 -> 2913.0439 | I7: =IS!I18 -> 3059.7017 | J7: =IS!J18 -> 3217.1767 | K7: =IS!K18 -> 3388.6149 | L7: =IS!L18 -> 3569.6341
B8: Adjustments to reconcile net income
B9: to net cash provided by operations:
B10: Depreciation and amortization | E10: 511 | F10: 519 | G10: 539 | H10: =-'Dep Capex '!H12-'Amort Intangible'!H12 -> 602.60769 | I10: =-'Dep Capex '!I12-'Amort Intangible'!I12 -> 633.11011 | J10: =-'Dep Capex '!J12-'Amort Intangible'!J12 -> 665.07856 | K10: =-'Dep Capex '!K12-'Amort Intangible'!K12 -> 698.63562 | L10: =-'Dep Capex '!L12-'Amort Intangible'!L12 -> 733.91514
B11: Restructuring and termination benefits, net of cash | E11: -7 | F11: 18 | G11: -71 | H11: 0 | I11: 0 | J11: 0 | K11: 0 | L11: 0
B12: Stock-based compensation expense | E12: 109 | F12: 100 | G12: 107 | H12: 0 | I12: 0 | J12: 0 | K12: 0 | L12: 0
B13: Loss on early extinguishment of debt | G13: 23 | H13: 0 | I13: 0 | J13: 0 | K13: 0 | L13: 0
B14: Charge for U.S. tax reform | E14: 80 | H14: 0 | I14: 0 | J14: 0 | K14: 0 | L14: 0
B15: Deferred income taxes | E15: 27 | F15: 17 | G15: -120 | H15: ='Other Long Term Asset Liability'!G9-'Other Long Term Asset Liability'!H9+'Other Long Term Asset Liability'!H13-'Other Long Term Asset Liability'!G13 -> 0 | I15: ='Other Long Term Asset Liability'!H9-'Other Long Term Asset Liability'!I9+'Other Long Term Asset Liability'!I13-'Other Long Term Asset Liability'!H13 -> 0 | J15: ='Other Long Term Asset Liability'!I9-'Other Long Term Asset Liability'!J9+'Other Long Term Asset Liability'!J13-'Other Long Term Asset Liability'!I13 -> 0 | K15: ='Other Long Term Asset Liability'!J9-'Other Long Term Asset Liability'!K9+'Other Long Term Asset Liability'!K13-'Other Long Term Asset Liability'!J13 -> 0 | L15: ='Other Long Term Asset Liability'!K9-'Other Long Term Asset Liability'!L9+'Other Long Term Asset Liability'!L13-'Other Long Term Asset Liability'!K13 -> 0
B16: Voluntary benefit plan contributions | E16: -67 | F16: -113 | H16: 0 | I16: 0 | J16: 0 | K16: 0 | L16: 0
B17: Cash effects of changes in:
B18: Receivables | E18: -79 | F18: 19 | G18: 138 | H18: ='Working Capital'!G10-'Working Capital'!H10 -> -303.07781 | I18: ='Working Capital'!H10-'Working Capital'!I10 -> 169.36258 | J18: ='Working Capital'!I10-'Working Capital'!J10 -> -314.21201 | K18: ='Working Capital'!J10-'Working Capital'!K10 -> 157.20513 | L18: ='Working Capital'!K10-'Working Capital'!L10 -> -327.4892
B19: Inventories | E19: -58 | F19: -77 | G19: -251 | H19: ='Working Capital'!G11-'Working Capital'!H11 -> 137.44515 | I19: ='Working Capital'!H11-'Working Capital'!I11 -> -288.98908 | J19: ='Working Capital'!I11-'Working Capital'!J11 -> 124.82639 | K19: ='Working Capital'!J11-'Working Capital'!K11 -> -302.76752 | L19: ='Working Capital'!K11-'Working Capital'!L11 -> 109.7789
B20: Accounts payable, accrued income tax & other accruals | E20: 18 | F20: 36 | G20: 520 | H20: =-('Working Capital'!G15-'Working Capital'!H15+'Working Capital'!G17-'Working Capital'!H17+'Working Capital'!G16-'Working Capital'!H16) -> -446.57733 | I20: =-('Working Capital'!H15-'Working Capital'!I15+'Working Capital'!H17-'Working Capital'!I17+'Working Capital'!H16-'Working Capital'!I16) -> 602.52938 | J20: =-('Working Capital'!I15-'Working Capital'!J15+'Working Capital'!I17-'Working Capital'!J17+'Working Capital'!I16-'Working Capital'!J16) -> -380.682 | K20: =-('Working Capital'!J15-'Working Capital'!K15+'Working Capital'!J17-'Working Capital'!K17+'Working Capital'!J16-'Working Capital'!K16) -> 957.12554 | L20: =-('Working Capital'!K15-'Working Capital'!L15+'Working Capital'!K17-'Working Capital'!L17+'Working Capital'!K16-'Working Capital'!L16) -> -668.13102
B21: Other non-current assets and liabilities | E21: -36 | F21: 87 | G21: -26 | H21: ='Other Long Term Asset Liability'!G10-'Other Long Term Asset Liability'!H10+'Other Long Term Asset Liability'!H14-'Other Long Term Asset Liability'!G14+'Working Capital'!G12-'Working Capital'!H12 -> -20.89409 | I21: ='Other Long Term Asset Liability'!H10-'Other Long Term Asset Liability'!I10+'Other Long Term Asset Liability'!I14-'Other Long Term Asset Liability'!H14+'Working Capital'!H12-'Working Capital'!I12 -> -25.216463 | J21: ='Other Long Term Asset Liability'!I10-'Other Long Term Asset Liability'!J10+'Other Long Term Asset Liability'!J14-'Other Long Term Asset Liability'!I14+'Working Capital'!I12-'Working Capital'!J12 -> -27.316188 | K21: ='Other Long Term Asset Liability'!J10-'Other Long Term Asset Liability'!K10+'Other Long Term Asset Liability'!K14-'Other Long Term Asset Liability'!J14+'Working Capital'!J12-'Working Capital'!K12 -> -29.608881 | L21: ='Other Long Term Asset Liability'!K10-'Other Long Term Asset Liability'!L10+'Other Long Term Asset Liability'!L14-'Other Long Term Asset Liability'!K14+'Working Capital'!K12-'Working Capital'!L12 -> -32.112739
B22: Net cash provided by operations | C22: =SUM(C7:C21) -> 0 | E22: =SUM(E7:E21) -> 3056 | F22: =SUM(F7:F21) -> 3133 | G22: =SUM(G7:G21) -> 3719 | H22: =SUM(H7:H21) -> 2882.5475 | I22: =SUM(I7:I21) -> 4150.4982 | J22: =SUM(J7:J21) -> 3284.8715 | K22: =SUM(K7:K21) -> 4869.2048 | L22: =SUM(L7:L21) -> 3385.5951
B24: Investing Activities
B25: Capital expenditures | E25: -436 | F25: -335 | G25: -410 | H25: =-'Dep Capex '!H7-'Amort Intangible'!H7 -> -861.1195 | I25: =-'Dep Capex '!I7-'Amort Intangible'!I7 -> -901.79121 | J25: =-'Dep Capex '!J7-'Amort Intangible'!J7 -> -945.84958 | K25: =-'Dep Capex '!K7-'Amort Intangible'!K7 -> -993.60584 | L25: =-'Dep Capex '!L7-'Amort Intangible'!L7 -> -1045.4006
B26: Purchases of marketable securities and investments | E26: -169 | F26: -184 | G26: -143
B27: Proceeds from sale of marketable securities and investments | E27: 156 | F27: 131 | G27: 124
B28: Payment for acquisitions, net of cash acquired | E28: -728 | F28: -1711 | G28: -353
B29: Other | E29: 7 | G29: 3
B30: Net cash used in investing activities | C30: =SUM(C25:C29) -> 0 | E30: =SUM(E25:E29) -> -1170 | F30: =SUM(F25:F29) -> -2099 | G30: =SUM(G25:G29) -> -779 | H30: =SUM(H25:H29) -> -861.1195 | I30: =SUM(I25:I29) -> -901.79121 | J30: =SUM(J25:J29) -> -945.84958 | K30: =SUM(K25:K29) -> -993.60584 | L30: =SUM(L25:L29) -> -1045.4006
B32: Cash Flow for Financing Activities | C32: =C30+C22 -> 0 | E32: =E30+E22 -> 1886 | F32: =F30+F22 -> 1034 | G32: =G30+G22 -> 2940 | H32: =H30+H22 -> 2021.428 | I32: =I30+I22 -> 3248.707 | J32: =J30+J22 -> 2339.0219 | K32: =K30+K22 -> 3875.5989 | L32: =L30+L22 -> 2340.1945
B34: Financing Activities
B35: Revolver | H35: =Debt!H19 -> 860.46853 | I35: =Debt!I19 -> -16.826318 | J35: =Debt!J19 -> 1570.3936 | K35: =Debt!K19 -> 0 | L35: =Debt!L19 -> 1243.0073
B36: Short-term borrowing/(repayment) less than 90 days - net | E36: 546 | F36: 294 | G36: 497
B37: Principal payments on debt | E37: -725 | F37: -1441 | G37: -1061 | H37: =Debt!H25 -> -631 | I37: =Debt!I25 -> -413 | J37: =Debt!J25 -> -896 | K37: =Debt!K25 -> -498 | L37: =Debt!L25 -> -130
B38: Proceeds from issuance of debt | F38: 2595
B39: Dividends paid | E39: -1591 | F39: -1614 | G39: -1654 | H39: =-'Shareholders Equity'!H30 -> -1642.9567 | I39: =-'Shareholders Equity'!I30 -> -1725.6717 | J39: =-'Shareholders Equity'!J30 -> -1814.4877 | K39: =-'Shareholders Equity'!K30 -> -1911.1788 | L39: =-'Shareholders Equity'!L30 -> -2013.2736
B40: Purchases of treasury shares | E40: -1238 | F40: -1202 | G40: -1476 | H40: =-'Shareholders Equity'!H18 -> -1499.9398 | I40: =-'Shareholders Equity'!I18 -> -1597.2089 | J40: =-'Shareholders Equity'!J18 -> -1702.9278 | K40: =-'Shareholders Equity'!K18 -> -1819.1451 | L40: =-'Shareholders Equity'!L18 -> -1943.9282
B41: Proceeds from exercise of stock options and excess tax benefits | E41: 329 | F41: 498 | G41: 874 | H41: ='Shareholders Equity'!H23 -> 504 | I41: ='Shareholders Equity'!I23 -> 504 | J41: ='Shareholders Equity'!J23 -> 504 | K41: ='Shareholders Equity'!K23 -> 504 | L41: ='Shareholders Equity'!L23 -> 504
B42: Purchases of non-controlling interests in subsidiaries | G42: -99
B43: Net cash used in financing activities | C43: =SUM(C37:C41) -> 0 | E43: =SUM(E36:E41) -> -2679 | F43: =SUM(F36:F41) -> -870 | G43: =SUM(G36:G42) -> -2919 | H43: =SUM(H35:H42) -> -2409.428 | I43: =SUM(I35:I42) -> -3248.707 | J43: =SUM(J35:J42) -> -2339.0219 | K43: =SUM(K35:K42) -> -3724.3239 | L43: =SUM(L35:L42) -> -2340.1945
B45: Effect of exchange rate changes on Cash and cash equivalents | E45: -16 | F45: -7 | G45: -16 | H45: 0 | I45: 0 | J45: 0 | K45: 0 | L45: 0
B46: Net increase (decrease) in Cash and cash equivalents | C46: =C22+C30+C43+C45 -> 0 | E46: =E22+E30+E43+E45 -> -809 | F46: =F22+F30+F43+F45 -> 157 | G46: =G22+G30+G43+G45 -> 5 | H46: =H22+H30+H43+H45 -> -388 | I46: =I22+I30+I43+I45 -> 0 | J46: =J22+J30+J43+J45 -> 0 | K46: =K22+K30+K43+K45 -> 151.27502 | L46: =L22+L30+L43+L45 -> 0
...

Sheet Working Capital
A1: =IS!A1 -> Colgate-Palmolive Company
A3: Consolidated Working Capital
C5: =BS!C5 -> 42735 | D5: =BS!D5 -> 43100 | E5: =BS!E5 -> 43465 | F5: =BS!F5 -> 43830 | G5: =BS!G5 -> 44196 | H5: =BS!H5 -> 44561 | I5: =BS!I5 -> 44926 | J5: =BS!J5 -> 45291 | ... L5: =BS!L5 -> 46022
B6: Net Sales | C6: =IS!C6 -> 15195 | D6: =IS!D6 -> 15454 | E6: =IS!E6 -> 15544 | F6: =IS!F6 -> 15693 | G6: =IS!G6 -> 16471 | H6: =IS!H6 -> 17222.39 | I6: =IS!I6 -> 18035.824 | J6: =IS!J6 -> 18916.992 | ... L6: =IS!L6 -> 20908.012
B7: Cost of Sales | C7: =IS!C7 -> 6072 | D7: =IS!D7 -> 6174 | E7: =IS!E7 -> 6313 | F7: =IS!F7 -> 6368 | G7: =IS!G7 -> 6454 | H7: =IS!H7 -> 6888.956 | I7: =IS!I7 -> 7214.3297 | J7: =IS!J7 -> 7566.7967 | ... L7: =IS!L7 -> 8363.2047
B9: Working Capital Balances
B10: Receivables | C10: =BS!C9 -> 1411 | D10: =BS!D9 -> 1480 | E10: =BS!E9 -> 1400 | F10: =BS!F9 -> 1440 | G10: =BS!G9 -> 1264 | H10: =2*H27*H6/$Q$10-G10 -> 1567.0778 | I10: =2*I27*I6/$Q$10-H10 -> 1397.7152 | J10: =2*J27*J6/$Q$10-I10 -> 1711.9272 | K10: =2*K27*K6/$Q$10-J10 -> 1554.7221 | L10: =2*L27*L6/$Q$10-K10 -> 1882.2113 | P10: Number of days assumption | Q10: 365
B11: Inventories | C11: =BS!C10 -> 1171 | D11: =BS!D10 -> 1221 | E11: =BS!E10 -> 1250 | F11: =BS!F10 -> 1400 | G11: =BS!G10 -> 1673 | H11: =2*H28*H7/$Q$10-G11 -> 1535.5548 | I11: =2*I28*I7/$Q$10-H11 -> 1824.5439 | J11: =2*J28*J7/$Q$10-I11 -> 1699.7175 | K11: =2*K28*K7/$Q$10-J11 -> 2002.4851 | L11: =2*L28*L7/$Q$10-K11 -> 1892.7062
B12: Other current assets | C12: =BS!C11 -> 441 | D12: =BS!D11 -> 403 | E12: =BS!E11 -> 417 | F12: =BS!F11 -> 456 | G12: =BS!G11 -> 513 | H12: =H6*H29 -> 533.89409 | I12: =I6*I29 -> 559.11055 | J12: =J6*J29 -> 586.42674 | K12: =K6*K29 -> 616.03562 | L12: =L6*L29 -> 648.14836
B13: Total Non Cash Current Assets | C13: =C10+C11+C12 -> 3023 | D13: =D10+D11+D12 -> 3104 | E13: =E10+E11+E12 -> 3067 | F13: =F10+F11+F12 -> 3296 | G13: =G10+G11+G12 -> 3450 | H13: =H10+H11+H12 -> 3636.5267 | I13: =I10+I11+I12 -> 3781.3697 | J13: =J10+J11+J12 -> 3998.0715 | ... L13: =L10+L11+L12 -> 4423.0658
B15: Accounts payable | C15: =BS!C25 -> 1124 | D15: =BS!D25 -> 1212 | E15: =BS!E25 -> 1222 | F15: =BS!F25 -> 1237 | G15: =BS!G25 -> 1393 | H15: =2*H31*H24/$Q$10-G15 -> 1196.6206 | I15: =2*I31*I24/$Q$10-H15 -> 1681.3647 | J15: =2*J31*J24/$Q$10-I15 -> 1173.0897 | K15: =2*K31*K24/$Q$10-J15 -> 1991.9131 | L15: =2*L31*L24/$Q$10-K15 -> 1173.7845
B16: Accrued income taxes | C16: =BS!C26 -> 441 | D16: =BS!D26 -> 354 | E16: =BS!E26 -> 411 | F16: =BS!F26 -> 370 | G16: =BS!G26 -> 403 | H16: =H7*H32 -> 427.11527 | I16: =I7*I32 -> 447.28844 | J16: =J7*J32 -> 469.14139 | K16: =K7*K32 -> 492.8285 | L16: =L7*L32 -> 518.51869
B17: Other accruals | C17: =BS!C27 -> 1727 | D17: =BS!D27 -> 1831 | E17: =BS!E27 -> 1696 | F17: =BS!F27 -> 1917 | G17: =BS!G27 -> 2341 | H17: =H7*H33 -> 2066.6868 | I17: =I7*I33 -> 2164.2989 | J17: =J7*J33 -> 2270.039 | K17: =K7*K33 -> 2384.654 | L17: =L7*L33 -> 2508.9614
B18: Total Non-Debt Current Liabilities | C18: =C15+C16+C17 -> 3292 | D18: =D15+D16+D17 -> 3397 | E18: =E15+E16+E17 -> 3329 | F18: =F15+F16+F17 -> 3524 | G18: =G15+G16+G17 -> 4137 | H18: =H15+H16+H17 -> 3690.4227 | I18: =I15+I16+I17 -> 4292.9521 | J18: =J15+J16+J17 -> 3912.2701 | ... L18: =L15+L16+L17 -> 4201.2646
B20: Net Working Capital/ (Deficit) | C20: =C13-C18 -> -269 | D20: =D13-D18 -> -293 | E20: =E13-E18 -> -262 | F20: =F13-F18 -> -228 | G20: =G13-G18 -> -687 | H20: =H13-H18 -> -53.895924 | I20: =I13-I18 -> -511.58235 | J20: =J13-J18 -> 85.801461 | ... L20: =L13-L18 -> 221.80126
B22: (Increase)/ Decrease in Working Capital | D22: =C20-D20 -> 24 | E22: =D20-E20 -> -31 | F22: =E20-F20 -> -34 | G22: =F20-G20 -> 459 | H22: =G20-H20 -> -633.10408 | I22: =H20-I20 -> 457.68642 | J22: =I20-J20 -> -597.38381 | K22: =J20-K20 -> 781.95426 | L22: =K20-L20 -> -917.95407
B24: Purchases | D24: =D7+D11-C11 -> 6224 | E24: =E7+E11-D11 -> 6342 | F24: =F7+F11-E11 -> 6518 | G24: =G7+G11-F11 -> 6727 | H24: =H7+H11-G11 -> 6751.5108 | I24: =I7+I11-H11 -> 7503.3188 | J24: =J7+J11-I11 -> 7441.9703 | K24: =K7+K11-J11 -> 8251.6143 | L24: =L7+L11-K11 -> 8253.4258
B26: Ratios & Assumptions
B27: Accounts Receivable, net (Collection period in days) | D27: =$Q$10/(D6/AVERAGE(C10,D10)) -> 34.140514 | E27: =$Q$10/(E6/AVERAGE(D10,E10)) -> 33.81369 | F27: =$Q$10/(F6/AVERAGE(E10,F10)) -> 33.027464 | G27: =$Q$10/(G6/AVERAGE(F10,G10)) -> 29.960537 | H27: 30 | I27: 30 | J27: 30 | K27: 30 | L27: 30
B28: Inventory (Days outstanding) | D28: =$Q$10/(D7/AVERAGE(C11,D11)) -> 70.706187 | E28: =$Q$10/(E7/AVERAGE(D11,E11)) -> 71.433154 | F28: =$Q$10/(F7/AVERAGE(E11,F11)) -> 75.946137 | G28: =$Q$10/(G7/AVERAGE(F11,G11)) -> 86.895336 | H28: 85 | I28: 85 | J28: 85 | K28: 85 | L28: 85
B29: Other Current Assets (% of Net Sales) | D29: =D12/D6 -> 0.026077391 | E29: =E12/E6 -> 0.026827072 | F29: =F12/F6 -> 0.029057542 | G29: =G12/G6 -> 0.03114565 | H29: 0.031 | I29: 0.031 | J29: 0.031 | K29: 0.031 | L29: 0.031
B31: Accounts Payable (Days Payable) | D31: =$Q$10/(D24/AVERAGE(D15,C15)) -> 68.496144 | E31: =$Q$10/(E24/AVERAGE(E15,D15)) -> 70.041785 | F31: =$Q$10/(F24/AVERAGE(F15,E15)) -> 68.850491 | G31: =$Q$10/(G24/AVERAGE(G15,F15)) -> 71.350528 | H31: 70 | I31: 70 | J31: 70 | K31: 70 | L31: 70
B32: Accrued Income Taxes (% of COGS) | D32: =D16/D7 -> 0.057337221 | E32: =E16/E7 -> 0.065103754 | F32: =F16/F7 -> 0.058103015 | G32: =G16/G7 -> 0.062441896 | H32: 0.062 | I32: 0.062 | J32: 0.062 | K32: 0.062 | L32: 0.062
B33: Other accruals (% of COGS) | D33: =D17/D7 -> 0.29656625 | E33: =E17/E7 -> 0.26865199 | F33: =F17/F7 -> 0.30103643 | G33: =G17/G7 -> 0.36272079 | H33: 0.3 | I33: 0.3 | J33: 0.3 | K33: 0.3 | L33: 0.3
B35: Cash Flow from Individual line items
B36: Receivables | E36: =D10-E10 -> 80 | F36: =E10-F10 -> -40 | G36: =F10-G10 -> 176 | H36: =G10-H10 -> -303.07781 | I36: =H10-I10 -> 169.36258 | J36: =I10-J10 -> -314.21201 | K36: =J10-K10 -> 157.20513 | L36: =K10-L10 -> -327.4892
B37: Inventories | E37: =D11-E11 -> -29 | F37: =E11-F11 -> -150 | G37: =F11-G11 -> -273 | H37: =G11-H11 -> 137.44515 | I37: =H11-I11 -> -288.98908 | J37: =I11-J11 -> 124.82639 | K37: =J11-K11 -> -302.76752 | L37: =K11-L11 -> 109.7789
B38: Other current assets | E38: =D12-E12 -> -14 | F38: =E12-F12 -> -39 | G38: =F12-G12 -> -57 | H38: =G12-H12 -> -20.89409 | I38: =H12-I12 -> -25.216463 | J38: =I12-J12 -> -27.316188 | K38: =J12-K12 -> -29.608881 | L38: =K12-L12 -> -32.112739
B39: Accounts payable | E39: =E15-D15 -> 10 | F39: =F15-E15 -> 15 | G39: =G15-F15 -> 156 | H39: =H15-G15 -> -196.3794 | I39: =I15-H15 -> 484.74409 | J39: =J15-I15 -> -508.27503 | K39: =K15-J15 -> 818.82341 | L39: =L15-K15 -> -818.12859
B40: Accrued income taxes | E40: =E16-D16 -> 57 | F40: =F16-E16 -> -41 | G40: =G16-F16 -> 33 | H40: =H16-G16 -> 24.115272 | I40: =I16-H16 -> 20.173171 | J40: =J16-I16 -> 21.85295 | K40: =K16-J16 -> 23.687105 | L40: =L16-K16 -> 25.690191
B41: Other accruals | E41: =E17-D17 -> -135 | F41: =F17-E17 -> 221 | G41: =G17-F17 -> 424 | H41: =H17-G17 -> -274.3132 | I41: =I17-H17 -> 97.612116 | J41: =J17-I17 -> 105.74008 | K41: =K17-J17 -> 114.61502 | L41: =L17-K17 -> 124.30738
B42: (Incease)/ Decrease in Working Capital | E42: =SUM(E36:E41) -> -31 | F42: =SUM(F36:F41) -> -34 | G42: =SUM(G36:G41) -> 459 | H42: =SUM(H36:H41) -> -633.10408 | I42: =SUM(I36:I41) -> 457.68642 | J42: =SUM(J36:J41) -> -597.38381 | K42: =SUM(K36:K41) -> 781.95426 | L42: =SUM(L36:L41) -> -917.95407
B44: Check | E44: =E22-E42 -> 0 | F44: =F22-F42 -> 0 | G44: =G22-G42 -> 0 | H44: =H22-H42 -> 0 | I44: =I22-I42 -> 0 | J44: =J22-J42 -> 0 | K44: =K22-K42 -> 0 | L44: =L22-L42 -> 0

Sheet Dep Capex 
A1: =IS!A1 -> Colgate-Palmolive Company
A3: Consolidated Depreciation and Capex
C5: =BS!C5 -> 42735 | D5: =BS!D5 -> 43100 | E5: =BS!E5 -> 43465 | F5: =BS!F5 -> 43830 | G5: =BS!G5 -> 44196 | H5: =BS!H5 -> 44561 | I5: =BS!I5 -> 44926 | J5: =BS!J5 -> 45291 | ... L5: =BS!L5 -> 46022
B6: Net Sales | C6: =IS!C6 -> 15195 | D6: =IS!D6 -> 15454 | E6: =IS!E6 -> 15544 | F6: =IS!F6 -> 15693 | G6: =IS!G6 -> 16471 | H6: =IS!H6 -> 17222.39 | I6: =IS!I6 -> 18035.824 | J6: =IS!J6 -> 18916.992 | ... L6: =IS!L6 -> 20908.012
B7: Capital Expenditures | E7: =CF!E25 -> -436 | F7: =CF!F25 -> -335 | G7: =CF!G25 -> -410 | H7: =H8*H6 -> 516.6717 | I7: =I8*I6 -> 541.07473 | J7: =J8*J6 -> 567.50975 | K7: =K8*K6 -> 596.16351 | L7: =L8*L6 -> 627.24035
B8: Capital Expenditures as % of Net Sales | E8: =ABS(E7/E6) -> 0.028049408 | F8: =ABS(F7/F6) -> 0.021347097 | G8: =ABS(G7/G6) -> 0.024892235 | H8: 0.03 | I8: 0.03 | J8: 0.03 | K8: 0.03 | L8: 0.03
B10: Beginning Net PP&E | H10: =G13 -> 3716 | I10: =H13 -> 3713.064 | J10: =I13 -> 3704.0286 | K10: =J13 -> 3689.4598 | L10: =K13 -> 3669.9877
B11: Capital Expenditures | H11: =H7 -> 516.6717 | I11: =I7 -> 541.07473 | J11: =J7 -> 567.50975 | K11: =K7 -> 596.16351 | L11: =L7 -> 627.24035
B12: (Depreciation Expense) | H12: =-H75 -> -519.60769 | I12: =-I75 -> -550.11011 | J12: =-J75 -> -582.07856 | K12: =-K75 -> -615.63562 | L12: =-L75 -> -650.91514
B13: Ending Net PP&E | C13: =BS!C14 -> 3840 | D13: =BS!D14 -> 4072 | E13: =BS!E14 -> 3881 | F13: =BS!F14 -> 3750 | G13: =BS!G14 -> 3716 | H13: =SUM(H10:H12) -> 3713.064 | I13: =SUM(I10:I12) -> 3704.0286 | J13: =SUM(J10:J12) -> 3689.4598 | K13: =SUM(K10:K12) -> 3669.9877 | L13: =SUM(L10:L12) -> 3646.3129
B16: PPE (Break-up) | F16: =F5 -> 43830 | G16: =G5 -> 44196 | H16: Remaining useful life | J16: Proportion of Assets
B17: Land | F17: 153 | G17: 166 | H17: NA | J17: =G17/$G$21 -> 0.018969261
B18: Building Improvements | F18: 1600 | G18: 1623 | H18: 40 | J18: =G18/$G$21 -> 0.18546452
B19: Machinery and equipment | F19: 5309 | G19: 5409 | H19: 15 | J19: =G19/$G$21 -> 0.61810079
B20: Other Equipment | F20: 1518 | G20: 1553 | H20: 15 | J20: =G20/$G$21 -> 0.17746543
B21: Total | F21: =SUM(F17:F20) -> 8580 | G21: =SUM(G17:G20) -> 8751
B24: Total Capex
B25: Breakup
B26: =B17 -> Land | H26: =$J17*H$7 -> 9.8008802 | I26: =$J17*I$7 -> 10.263788 | J26: =$J17*J$7 -> 10.76524 | K26: =$J17*K$7 -> 11.308781 | L26: =$J17*L$7 -> 11.898286
B27: =B18 -> Building Improvements | H27: =$J18*H$7 -> 95.824268 | I27: =$J18*I$7 -> 100.35016 | J27: =$J18*J$7 -> 105.25292 | K27: =$J18*K$7 -> 110.56718 | L27: =$J18*L$7 -> 116.33083
B28: =B19 -> Machinery and equipment | H28: =$J19*H$7 -> 319.35519 | I28: =$J19*I$7 -> 334.43872 | J28: =$J19*J$7 -> 350.77822 | K28: =$J19*K$7 -> 368.48913 | L28: =$J19*L$7 -> 387.69775
B29: =B20 -> Other Equipment | H29: =$J20*H$7 -> 91.691367 | I29: =$J20*I$7 -> 96.022061 | J29: =$J20*J$7 -> 100.71336 | K29: =$J20*K$7 -> 105.79841 | L29: =$J20*L$7 -> 111.31348
B32: Building Improvements - Straight Line Method
B33: Useful Life | C33: =H18 -> 40 | D33: Years
B34: Building Improvement | C34: =G18 -> 1623 | H34: =$C$34/$C33 -> 40.575 | I34: =$C$34/$C33 -> 40.575 | J34: =$C$34/$C33 -> 40.575 | K34: =$C$34/$C33 -> 40.575 | L34: =$C$34/$C33 -> 40.575
B35: Depreciation Expense (existing)
C37: Capex | D37: Useful Life
B38: 2021 | C38: {=TRANSPOSE(H27:L27)} -> 95.824268 | D38: =$C$33 -> 40 | E38: Years | H38: =$C38/$D38/2 -> 1.1978033 | I38: =$C38/$D38 -> 2.3956067 | J38: =$C38/$D38 -> 2.3956067 | K38: =$C38/$D38 -> 2.3956067 | L38: =$C38/$D38 -> 2.3956067
B39: =B38+1 -> 2022 | C39: 100.35016 | D39: =$C$33 -> 40 | I39: =$C39/$D39/2 -> 1.2543771 | J39: =$C39/$D39 -> 2.5087541 | K39: =$C39/$D39 -> 2.5087541 | L39: =$C39/$D39 -> 2.5087541
B40: =B39+1 -> 2023 | C40: 105.25292 | D40: =$C$33 -> 40 | J40: =$C40/$D40/2 -> 1.3156615 | K40: =$C40/$D40 -> 2.6313231 | L40: =$C40/$D40 -> 2.6313231
B41: =B40+1 -> 2024 | C41: 110.56718 | D41: =$C$33 -> 40 | K41: =$C41/$D41/2 -> 1.3820897 | L41: =$C41/$D41 -> 2.7641794
B42: =B41+1 -> 2025 | C42: 116.33083 | D42: =$C$33 -> 40 | L42: =$C42/$D42/2 -> 1.4541354
B44: Depreciation (Building Improvements) | H44: =SUM(H34:H43) -> 41.772803 | I44: =SUM(I34:I43) -> 44.224984 | J44: =SUM(J34:J43) -> 46.795022 | K44: =SUM(K34:K43) -> 49.492774 | L44: =SUM(L34:L43) -> 52.328999
B46: Machinery & Equipments
B47: Useful Life | C47: =H19 -> 15 | D47: Years
B48: Machinery & Equipments | C48: =G19 -> 5409 | H48: =$C$48/$C47 -> 360.6 | I48: =$C$48/$C47 -> 360.6 | J48: =$C$48/$C47 -> 360.6 | K48: =$C$48/$C47 -> 360.6 | L48: =$C$48/$C47 -> 360.6
B49: Depreciation Expense (existing)
C51: Capex | D51: Useful Life
B52: 2021 | C52: {=TRANSPOSE(H28:L28)} -> 319.35519 | D52: =$C$47 -> 15 | E52: Years | H52: =$C$52/$D52/2 -> 10.645173 | I52: =$C$52/$D52 -> 21.290346 | J52: =$C$52/$D52 -> 21.290346 | K52: =$C$52/$D52 -> 21.290346 | L52: =$C$52/$D52 -> 21.290346
B53: =B52+1 -> 2022 | C53: 334.43872 | D53: =$C$47 -> 15 | I53: =$C$53/$D53/2 -> 11.147957 | J53: =$C$53/$D53 -> 22.295914 | K53: =$C$53/$D53 -> 22.295914 | L53: =$C$53/$D53 -> 22.295914
...

Sheet Amort Intangible
A1: =IS!A1 -> Colgate-Palmolive Company
A3: Consolidated Amortization & Intangible
C5: =BS!C5 -> 42735 | D5: =BS!D5 -> 43100 | E5: =BS!E5 -> 43465 | F5: =BS!F5 -> 43830 | G5: =BS!G5 -> 44196 | H5: =BS!H5 -> 44561 | I5: =BS!I5 -> 44926 | J5: =BS!J5 -> 45291 | ... L5: =BS!L5 -> 46022
B6: Net Sales | C6: =IS!C$6 -> 15195 | D6: =IS!D$6 -> 15454 | E6: =IS!E$6 -> 15544 | F6: =IS!F$6 -> 15693 | G6: =IS!G$6 -> 16471 | H6: =IS!H$6 -> 17222.39 | I6: =IS!I$6 -> 18035.824 | J6: =IS!J$6 -> 18916.992 | ... L6: =IS!L$6 -> 20908.012
B7: Additions to Intangibles | E7: =2128-1781 -> 347 | F7: =3217-2128 -> 1089 | G7: =3553-3217 -> 336 | H7: =H6*H8 -> 344.4478 | I7: =I6*I8 -> 360.71649 | J7: =J6*J8 -> 378.33983 | K7: =K6*K8 -> 397.44234 | L7: =L6*L8 -> 418.16023
B8: Additions to Intangibles as % of Net Sales | E8: =E7/E6 -> 0.022323726 | F8: =F7/F6 -> 0.069393997 | G8: =G7/G6 -> 0.02039949 | H8: 0.02 | I8: 0.02 | J8: 0.02 | K8: 0.02 | L8: 0.02
B10: Beginning Net Intangibles | H10: =G13 -> 2894 | I10: =H13 -> 3155.4478 | J10: =I13 -> 3433.1643 | K10: =J13 -> 3728.5041 | L10: =K13 -> 4042.9465
B11: Additions to Intangibles | H11: =H7 -> 344.4478 | I11: =I7 -> 360.71649 | J11: =J7 -> 378.33983 | K11: =K7 -> 397.44234 | L11: =L7 -> 418.16023
B12: (Amortization Expense) | F12: -62 | G12: -88 | H12: -83 | I12: -83 | J12: -83 | K12: -83 | L12: -83
B13: Ending Net Intangibles | G13: =BS!G16 -> 2894 | H13: =SUM(H10:H12) -> 3155.4478 | I13: =SUM(I10:I12) -> 3433.1643 | J13: =SUM(J10:J12) -> 3728.5041 | K13: =SUM(K10:K12) -> 4042.9465 | L13: =SUM(L10:L12) -> 4378.1067

Sheet Other Long Term Asset Liability
A1: =IS!A1 -> Colgate-Palmolive Company
A3: Other Long Term Asset Liability Schedule
C5: =BS!C5 -> 42735 | D5: =BS!D5 -> 43100 | E5: =BS!E5 -> 43465 | F5: =BS!F5 -> 43830 | G5: =BS!G5 -> 44196 | H5: =BS!H5 -> 44561 | I5: =BS!I5 -> 44926 | J5: =BS!J5 -> 45291 | ... L5: =BS!L5 -> 46022
A7: Assets
B8: Goodwill, net | C8: =BS!C15 -> 2107 | D8: =BS!D15 -> 2218 | E8: =BS!E15 -> 2530 | F8: =BS!F15 -> 3508 | G8: =BS!$G$15 -> 3824 | H8: =BS!$G$15 -> 3824 | I8: =BS!$G$15 -> 3824 | J8: =BS!$G$15 -> 3824 | K8: =BS!$G$15 -> 3824 | L8: =BS!$G$15 -> 3824
B9: Deferred income taxes | C9: =BS!C17 -> 301 | D9: =BS!D17 -> 188 | E9: =BS!E17 -> 152 | F9: =BS!F17 -> 177 | G9: =BS!$G$17 -> 291 | H9: =BS!$G$17 -> 291 | I9: =BS!$G$17 -> 291 | J9: =BS!$G$17 -> 291 | K9: =BS!$G$17 -> 291 | L9: =BS!$G$17 -> 291
B10: Other assets | C10: =BS!C18 -> 224 | D10: =BS!D18 -> 218 | E10: =BS!E18 -> 168 | F10: =BS!F18 -> 753 | G10: =BS!$G$18 -> 857 | H10: =BS!$G$18 -> 857 | I10: =BS!$G$18 -> 857 | J10: =BS!$G$18 -> 857 | K10: =BS!$G$18 -> 857 | L10: =BS!$G$18 -> 857
A12: Liability
B13: Deferred income taxes | C13: =BS!C33 -> 246 | D13: =BS!D33 -> 204 | E13: =BS!E33 -> 235 | F13: =BS!F33 -> 507 | G13: =BS!$G$33 -> 426 | H13: =BS!$G$33 -> 426 | I13: =BS!$G$33 -> 426 | J13: =BS!$G$33 -> 426 | K13: =BS!$G$33 -> 426 | L13: =BS!$G$33 -> 426
B14: Other liabilities | C14: =BS!C34 -> 2035 | D14: =BS!D34 -> 2255 | E14: =BS!E34 -> 2034 | F14: =BS!F34 -> 2598 | G14: =BS!$G$34 -> 2655 | H14: =BS!$G$34 -> 2655 | I14: =BS!$G$34 -> 2655 | J14: =BS!$G$34 -> 2655 | K14: =BS!$G$34 -> 2655 | L14: =BS!$G$34 -> 2655

Sheet Shareholders Equity
A1: =IS!A1 -> Colgate-Palmolive Company
A3: Consolidated Shareholder's Equity
C5: =BS!C5 -> 42735 | D5: =BS!D5 -> 43100 | E5: =BS!E5 -> 43465 | F5: =BS!F5 -> 43830 | G5: =BS!G5 -> 44196 | H5: =BS!H5 -> 44561 | I5: =BS!I5 -> 44926 | J5: =BS!J5 -> 45291 | ... L5: =BS!L5 -> 46022
B6: Beginning Equity Balance | H6: =G11 -> 743 | I6: =H11 -> 842.36473 | J6: =I11 -> 899.60363 | K6: =J11 -> 910.3343 | L6: =K11 -> 869.30839
B7: Net Income | H7: =IS!H20 -> 2738.2612 | I7: =IS!I20 -> 2876.1196 | J7: =IS!J20 -> 3024.1461 | K7: =IS!K20 -> 3185.298 | L7: =IS!L20 -> 3355.456
B8: Issuance/ (Repurchase) of Equity | H8: =-H18 -> -1499.9398 | I8: =-I18 -> -1597.2089 | J8: =-J18 -> -1702.9278 | K8: =-K18 -> -1819.1451 | L8: =-L18 -> -1943.9282
B9: Dividends Paid | H9: =-H30 -> -1642.9567 | I9: =-I30 -> -1725.6717 | J9: =-J30 -> -1814.4877 | K9: =-K30 -> -1911.1788 | L9: =-L30 -> -2013.2736
B10: Option Proceeds | H10: =H23 -> 504 | I10: =I23 -> 504 | J10: =J23 -> 504 | K10: =K23 -> 504 | L10: =L23 -> 504
B11: Ending Equity Balance | C11: =BS!C44 -> -243 | D11: =BS!D44 -> -60 | E11: =BS!E44 -> -102 | F11: =BS!F44 -> 117 | G11: =BS!G44 -> 743 | H11: =SUM(H6:H10) -> 842.36473 | I11: =SUM(I6:I10) -> 899.60363 | J11: =SUM(J6:J10) -> 910.3343 | K11: =SUM(K6:K10) -> 869.30839 | L11: =SUM(L6:L10) -> 771.56256
B13: Share Repurchase Assumptions
B14: Current Year EPS | E14: =IS!E22 -> 2.75 | F14: =IS!F22 -> 2.75 | G14: =IS!G22 -> 3.14 | H14: =IS!H22 -> 3.243113 | I14: =IS!I22 -> 3.4534247 | J14: =IS!J22 -> 3.682006 | K14: =IS!K22 -> 3.9332867 | L14: =IS!L22 -> 4.2030881
B15: Assumed Current Year EPS Multiple | E15: =E16/E14 -> 23.962543 | F15: =F16/F14 -> 25.383275 | G15: =G16/G14 -> 25.134619 | H15: 25 | I15: 25 | J15: 25 | K15: 25 | L15: 25
B16: Implied Share Price | E16: =E18/E17 -> 65.896992 | F16: =F18/F17 -> 69.804006 | G16: =G18/G17 -> 78.922703 | H16: =H14*H15 -> 81.077825 | I16: =I14*I15 -> 86.335618 | J16: =J14*J15 -> 92.05015 | K16: =K14*K15 -> 98.332168 | L16: =L14*L15 -> 105.0772
B17: Shares Repurchased (in millions) | E17: 18.786897 | F17: 17.219642 | G17: 18.701843 | H17: 18.5 | I17: 18.5 | J17: 18.5 | K17: 18.5 | L17: 18.5
B18: Amount Repurchased ( $ outgo) | E18: =ABS(CF!E40) -> 1238 | F18: =ABS(CF!F40) -> 1202 | G18: =ABS(CF!G40) -> 1476 | H18: =H17*H16 -> 1499.9398 | I18: =I17*I16 -> 1597.2089 | J18: =J17*J16 -> 1702.9278 | K18: =K17*K16 -> 1819.1451 | L18: =L17*L16 -> 1943.9282
B20: New Shares from Exercised Options
B21: New Shares from Exercised Options - millions | E21: 6.04092 | F21: 8.145777 | G21: 13.018354 | H21: 7 | I21: 7 | J21: 7 | K21: 7 | L21: 7
B22: Average Strike Price | E22: =E23/E21 -> 54.461903 | F22: =F23/F21 -> 61.135973 | G22: =G23/G21 -> 67.135984 | H22: 72 | I22: 72 | J22: 72 | K22: 72 | L22: 72
B23: Option Proceeds | E23: =CF!E41 -> 329 | F23: =CF!F41 -> 498 | G23: =CF!G41 -> 874 | H23: =H21*H22 -> 504 | I23: =I21*I22 -> 504 | J23: =J21*J22 -> 504 | K23: =K21*K22 -> 504 | L23: =L21*L22 -> 504
B25: Restricted Stock Units (RSUs) | E25: 0.957651 | F25: 0.862852 | G25: 0.875311 | H25: =8.65/3 -> 2.8833333 | I25: =8.65/3 -> 2.8833333 | J25: =8.65/3 -> 2.8833333 | K25: =8.65/3 -> 2.8833333 | L25: =8.65/3 -> 2.8833333
B29: Dividend Assumptions
B30: Total Dividends Paid | E30: =ABS(CF!E39) -> 1591 | F30: =ABS(CF!F39) -> 1614 | G30: =ABS(CF!G39) -> 1654 | H30: =H31*H32 -> 1642.9567 | I30: =I31*I32 -> 1725.6717 | J30: =J31*J32 -> 1814.4877 | K30: =K31*K32 -> 1911.1788 | L30: =L31*L32 -> 2013.2736
B31: Net Income | E31: =IS!E20 -> 2400 | F31: =IS!F20 -> 2367 | G31: =IS!G20 -> 2695 | H31: =IS!H20 -> 2738.2612 | I31: =IS!I20 -> 2876.1196 | J31: =IS!J20 -> 3024.1461 | K31: =IS!K20 -> 3185.298 | L31: =IS!L20 -> 3355.456
B32: Dividend Payout Ratio | E32: =E30/E31 -> 0.66291667 | F32: =F30/F31 -> 0.68187579 | G32: =G30/G31 -> 0.61372913 | H32: 0.6 | I32: 0.6 | J32: 0.6 | K32: 0.6 | L32: 0.6
E34: `

Sheet Shares Outstanding 
A1: =IS!A1 -> Colgate-Palmolive Company
A3: Consolidated Shares Outstanding
C5: =BS!C5 -> 42735 | D5: =BS!D5 -> 43100 | E5: =BS!E5 -> 43465 | F5: =BS!F5 -> 43830 | G5: =BS!G5 -> 44196 | H5: =BS!H5 -> 44561 | I5: =BS!I5 -> 44926 | J5: =BS!J5 -> 45291 | ... L5: =BS!L5 -> 46022
B6: Beginning Balance - Basic (actual) | E6: =D9 -> 874.70112 | F6: =E9 -> 861.95514 | G6: =F9 -> 852.88128 | H6: =G9 -> 847.19779 | I6: =H9 -> 835.69779 | J6: =I9 -> 824.19779 | K6: =J9 -> 812.69779 | L6: =K9 -> 801.19779
B7: Shares Issued (actual realization of options) | E7: ='Shareholders Equity'!E21 -> 6.04092 | F7: ='Shareholders Equity'!F21 -> 8.145777 | G7: ='Shareholders Equity'!G21 -> 13.018354 | H7: ='Shareholders Equity'!H21 -> 7 | I7: ='Shareholders Equity'!I21 -> 7 | J7: ='Shareholders Equity'!J21 -> 7 | K7: ='Shareholders Equity'!K21 -> 7 | L7: ='Shareholders Equity'!L21 -> 7
B8: Shares Repurchased | E8: =-'Shareholders Equity'!E17 -> -18.786897 | F8: =-'Shareholders Equity'!F17 -> -17.219642 | G8: =-'Shareholders Equity'!G17 -> -18.701843 | H8: =-'Shareholders Equity'!H17 -> -18.5 | I8: =-'Shareholders Equity'!I17 -> -18.5 | J8: =-'Shareholders Equity'!J17 -> -18.5 | K8: =-'Shareholders Equity'!K17 -> -18.5 | L8: =-'Shareholders Equity'!L17 -> -18.5
B9: Ending Balance - Basic (actual) | D9: 874.70112 | E9: =SUM(E6:E8) -> 861.95514 | F9: =SUM(F6:F8) -> 852.88128 | G9: =SUM(G6:G8) -> 847.19779 | H9: =SUM(H6:H8) -> 835.69779 | I9: =SUM(I6:I8) -> 824.19779 | J9: =SUM(J6:J8) -> 812.69779 | K9: =SUM(K6:K8) -> 801.19779 | L9: =SUM(L6:L8) -> 789.69779
B11: Basic Weighted Average Shares | E11: 870.6 | F11: 859.1 | G11: 856.8 | H11: =AVERAGE(G9:H9) -> 841.44779 | I11: =AVERAGE(H9:I9) -> 829.94779 | J11: =AVERAGE(I9:J9) -> 818.44779 | K11: =AVERAGE(J9:K9) -> 806.94779 | L11: =AVERAGE(K9:L9) -> 795.44779
B12: Restricted Stock Units | E12: 2.4 | F12: 2 | G12: 2.5 | H12: ='Shareholders Equity'!H25 -> 2.8833333 | I12: ='Shareholders Equity'!I25 -> 2.8833333 | J12: ='Shareholders Equity'!J25 -> 2.8833333 | K12: ='Shareholders Equity'!K25 -> 2.8833333 | L12: ='Shareholders Equity'!L25 -> 2.8833333
B13: Diluted Weighted Average Shares | E13: =SUM(E11:E12) -> 873 | F13: =SUM(F11:F12) -> 861.1 | G13: =SUM(G11:G12) -> 859.3 | H13: =SUM(H11:H12) -> 844.33112 | I13: =SUM(I11:I12) -> 832.83112 | J13: =SUM(J11:J12) -> 821.33112 | K13: =SUM(K11:K12) -> 809.83112 | L13: =SUM(L11:L12) -> 798.33112

Sheet Debt
A1: =IS!A1 -> Colgate-Palmolive Company
A3: Debt Schedule
C5: =BS!C5 -> 42735 | D5: =BS!D5 -> 43100 | E5: =BS!E5 -> 43465 | F5: =BS!F5 -> 43830 | G5: =BS!G5 -> 44196 | H5: =BS!H5 -> 44561 | I5: =BS!I5 -> 44926 | J5: =BS!J5 -> 45291 | ... L5: =BS!L5 -> 46022
B6: Cash Flow Available for Financing Activities | H6: =CF!H32 -> 2021.428 | I6: =CF!I32 -> 3248.707 | J6: =CF!J32 -> 2339.0219 | K6: =CF!K32 -> 3875.5989 | L6: =CF!L32 -> 2340.1945
B7: Proceeds from/ (Repurchase of) Equity | H7: =-'Shareholders Equity'!H18 -> -1499.9398 | I7: =-'Shareholders Equity'!I18 -> -1597.2089 | J7: =-'Shareholders Equity'!J18 -> -1702.9278 | K7: =-'Shareholders Equity'!K18 -> -1819.1451 | L7: =-'Shareholders Equity'!L18 -> -1943.9282
B8: Dividends | H8: =-'Shareholders Equity'!H30 -> -1642.9567 | I8: =-'Shareholders Equity'!I30 -> -1725.6717 | J8: =-'Shareholders Equity'!J30 -> -1814.4877 | K8: =-'Shareholders Equity'!K30 -> -1911.1788 | L8: =-'Shareholders Equity'!L30 -> -2013.2736
B9: Option Proceeds | H9: ='Shareholders Equity'!H23 -> 504 | I9: ='Shareholders Equity'!I23 -> 504 | J9: ='Shareholders Equity'!J23 -> 504 | K9: ='Shareholders Equity'!K23 -> 504 | L9: ='Shareholders Equity'!L23 -> 504
B10: + Beginning Cash Balance | H10: =BS!G8 -> 888 | I10: 500 | J10: 500 | K10: 500 | L10: 500
B11: - Minimum Cash Balance | H11: -500 | I11: -500 | J11: -500 | K11: -500 | L11: -500
B12: Cash Available for Debt Repayment | H12: =SUM(H6:H11) -> -229.46853 | I12: =SUM(I6:I11) -> 429.82632 | J12: =SUM(J6:J11) -> -674.39355 | K12: =SUM(K6:K11) -> 649.27502 | L12: =SUM(L6:L11) -> -1113.0073
B13: Long Term Debt Issuance | H13: =H24 -> 0 | I13: =I24 -> 0 | J13: =J24 -> 0 | K13: =K24 -> 0 | L13: =L24 -> 0
B14: Long Term Debt (Repayments) | H14: =H25 -> -631 | I14: =I25 -> -413 | J14: =J25 -> -896 | K14: =K25 -> -498 | L14: =L25 -> -130
B15: Cash Available for Revolving Credit Facility | H15: =SUM(H12:H14) -> -860.46853 | I15: =SUM(I12:I14) -> 16.826318 | J15: =SUM(J12:J14) -> -1570.3936 | K15: =SUM(K12:K14) -> 151.27502 | L15: =SUM(L12:L14) -> -1243.0073
B17: Revolving Credit Facility
B18: Beginning Balance | H18: =G20 -> 0 | I18: =H19 -> 860.46853 | J18: =I20 -> 843.64221 | K18: =J20 -> 2414.0358 | L18: =K20 -> 2414.0358
B19: Discretionary (Paydown)/ Borrowings | H19: =IF(H15<0,-H15,-MIN(H15,H18)) -> 860.46853 | I19: =IF(I15<0,-I15,-MIN(I15,I18)) -> -16.826318 | J19: =IF(J15<0,-J15,-MIN(J15,J18)) -> 1570.3936 | K19: 0 | L19: =IF(L15<0,-L15,-MIN(L15,L18)) -> 1243.0073
B20: Ending Balance | G20: 0 | H20: =SUM(H18:H19) -> 860.46853 | I20: =SUM(I18:I19) -> 843.64221 | J20: =SUM(J18:J19) -> 2414.0358 | K20: =SUM(K18:K19) -> 2414.0358 | L20: =SUM(L18:L19) -> 3657.0431
B22: Debt (Long Term + Current Debt)
B23: Beginning Balance | H23: =G26 -> 7343 | I23: =H26 -> 6712 | J23: =I26 -> 6299 | K23: =J26 -> 5403 | L23: =K26 -> 4905
B24: Issuance
B25: (Repayment/ Amortization) | H25: -631 | I25: -413 | J25: -896 | K25: -498 | L25: -130 | M25: -100
B26: Ending Balance | C26: =BS!C32+BS!C24 -> 6520 | D26: =BS!D32+BS!D24 -> 6566 | E26: =BS!E32+BS!E24 -> 6354 | F26: =BS!F32+BS!F24 -> 7587 | G26: =BS!G32+BS!G24 -> 7343 | H26: =SUM(H23:H25) -> 6712 | I26: =SUM(I23:I25) -> 6299 | J26: =SUM(J23:J25) -> 5403 | K26: =SUM(K23:K25) -> 4905 | L26: =SUM(L23:L25) -> 4775
B28: Long Term Debt | H28: =ABS(H26-H29) -> 6299 | I28: =I26-I29 -> 5403 | J28: =J26-J29 -> 4905 | K28: =K26-K29 -> 4775 | L28: =L26-L29 -> 4675
B29: Current Portion of Long Term Debt | H29: =ABS(I25) -> 413 | I29: =ABS(J25) -> 896 | J29: =ABS(K25) -> 498 | K29: =ABS(L25) -> 130 | L29: =ABS(M25) -> 100
B33: Revolving Credit Facility | F33: Average Balance | H33: =AVERAGE(G20:H20) -> 430.23426 | I33: =AVERAGE(H20:I20) -> 852.05537 | J33: =AVERAGE(I20:J20) -> 1628.839 | K33: =AVERAGE(J20:K20) -> 2414.0358 | L33: =AVERAGE(K20:L20) -> 3035.5394
F34: Interest Rate | H34: 0.015 | I34: 0.015 | J34: 0.015 | K34: 0.015 | L34: 0.015
F35: Interest Expense | H35: =H33*H34 -> 6.4535139 | I35: =I33*I34 -> 12.78083 | J35: =J33*J34 -> 24.432585 | K35: =K33*K34 -> 36.210536 | L35: =L33*L34 -> 45.533091
B38: Long Term Debt | C38: Average Balance | E38: =AVERAGE(D26:E26) -> 6460 | F38: =AVERAGE(E26:F26) -> 6970.5 | G38: =AVERAGE(F26:G26) -> 7465 | H38: =AVERAGE(G26:H26) -> 7027.5 | I38: =AVERAGE(H26:I26) -> 6505.5 | J38: =AVERAGE(I26:J26) -> 5851 | K38: =AVERAGE(J26:K26) -> 5154 | L38: =AVERAGE(K26:L26) -> 4840
C39: Interest Rate | E39: =E40/E38 -> 0.022136223 | F39: =F40/F38 -> 0.020801951 | G39: =G40/G38 -> 0.02196919 | H39: 0.022 | I39: 0.022 | J39: 0.022 | K39: 0.022 | L39: 0.022
C40: Interest Expense | E40: =IS!E14 -> 143 | F40: =IS!F14 -> 145 | G40: =IS!G14 -> 164 | H40: =H38*H39 -> 154.605 | I40: =I38*I39 -> 143.121 | J40: =J38*J39 -> 128.722 | K40: =K38*K39 -> 113.388 | L40: =L38*L39 -> 106.48
B42: Total Interest Expense | H42: =H40+H35 -> 161.05851 | I42: =I40+I35 -> 155.90183 | J42: =J40+J35 -> 153.15458 | K42: =K40+K35 -> 149.59854 | L42: =L40+L35 -> 152.01309
B45: Cash Balances | F45: Average Balance | H45: =AVERAGE(CF!G49:H49) -> 694 | I45: =AVERAGE(CF!H49:I49) -> 500 | J45: =AVERAGE(CF!I49:J49) -> 500 | K45: =AVERAGE(CF!J49:K49) -> 575.63751 | L45: =AVERAGE(CF!K49:L49) -> 651.27502
F46: Interest Rate | H46: 0.005 | I46: 0.005 | J46: 0.005 | K46: 0.005 | L46: 0.005
F47: Interest Income | H47: =H45*H46 -> 3.47 | I47: =I45*I46 -> 2.5 | J47: =J45*J46 -> 2.5 | K47: =K45*K46 -> 2.8781876 | L47: =L45*L46 -> 3.2563751
