Workbook
Name IQ_CH: 110000
Name IQ_CQ: 5000
Name IQ_CY: 10000
Name IQ_DAILY: 500000
Name IQ_FH: 100000
Name IQ_FQ: 500
Name IQ_FY: 1000
Name IQ_LTM: 2000
Name IQ_MONTH: 15000
Name IQ_NTM: 6000
Name IQ_WEEK: 50000
Name IQ_YTD: 3000

Sheet IS
A1: Microsoft Corp | Income Statement 10-Feb-2022 16:53
A3: Income Statement
A4: Annual Standardised in Millions of U.S. Dollars
C5: 2021 | D5: 2020 | E5: 2019 | F5: 2018 | G5: 2017
A6: Earnings Quality Score | C6: 86 | D6: 94 | E6: 85 | F6: 98 | G6: 88
A7: Period End Date | C7: 30-Jun-2021 | D7: 30-Jun-2020 | E7: 30-Jun-2019 | F7: 30-Jun-2018 | G7: 30-Jun-2017
A8: Original Announcement Date | C8: 27-Jul-2021 20:42 | D8: 22-Jul-2020 20:03 | E8: 18-Jul-2019 20:04 | F8: 19-Jul-2018 20:04 | G8: 19-Jul-2018 20:04
A9: Revenue | C9: 168088 | D9: 143015 | E9: 125843 | F9: 110360 | G9: 96571
A10: Net Sales | C10: 168088 | D10: 143015 | E10: 125843 | F10: 110360 | G10: 96571
A11: Other Revenue, Total | C11: -- | D11: -- | E11: -- | F11: -- | G11: --
A12: Total Revenue | C12: 168088 | D12: 143015 | E12: 125843 | F12: 110360 | G12: 96571
A13: Cost of Revenue, Total | C13: 52232 | D13: 46078 | E13: 42910 | F13: 38353 | G13: 34261
A14: Cost of Revenue | C14: 52232 | D14: 46078 | E14: 42910 | F14: 38353 | G14: 34261
A15: Gross Profit | C15: 115856 | D15: 96937 | E15: 82933 | F15: 72007 | G15: 62310
A17: Selling/General/Admin. Expenses, Total | C17: 25224 | D17: 24709 | E17: 23098 | F17: 22223 | G17: 18648
A18: Selling/General/Administrative Expense | C18: 23724 | D18: 23109 | E18: 21498 | F18: 20623 | G18: 17348
A19: Advertising Expense | C19: 1500 | D19: 1600 | E19: 1600 | F19: 1600 | G19: 1300
A20: Research & Development | C20: 20716 | D20: 19269 | E20: 16876 | F20: 14726 | G20: 12292
A21: Depreciation/Amortization | C21: -- | D21: -- | E21: -- | F21: -- | G21: --
A22: Interest Expense, Net - Operating | C22: -- | D22: -- | E22: -- | F22: -- | G22: --
A23: Interest/Investment Income - Operating | C23: -- | D23: -- | E23: -- | F23: -- | G23: --
A24: Interest Expense(Income) - Net Operating | C24: -- | D24: -- | E24: -- | F24: -- | G24: --
A25: Interest Exp.(Inc.),Net-Operating, Total | C25: -- | D25: -- | E25: -- | F25: -- | G25: --
A26: Unusual Expense (Income) | C26: 13 | D26: 133 | E26: 26 | F26: 47 | G26: 2400
A27: Restructuring Charge | C27: -- | D27: -- | E27: 0 | F27: 0 | G27: 306
A28: Impairment-Assets Held for Sale | C28: 13 | D28: 133 | E28: 26 | F28: 47 | G28: 55
A29: Other Unusual Expense (Income) | C29: -- | D29: -- | E29: -- | F29: -- | G29: 2039
A30: Other Operating Expenses, Total | C30: -- | D30: -- | E30: -- | F30: -- | G30: --
A31: Total Operating Expense | C31: 98185 | D31: 90189 | E31: 82910 | F31: 75349 | G31: 67601
A32: Operating Income | C32: 69903 | D32: 52826 | E32: 42933 | F32: 35011 | G32: 28970
A33: Interest Expense, Net Non-Operating | C33: -2346 | D33: -2591 | E33: -2686 | F33: -2733 | G33: -2222
A34: Interest Expense - Non-Operating | C34: -2346 | D34: -2591 | E34: -2686 | F34: -2733 | G34: -2222
A35: Interest/Invest Income - Non-Operating | C35: 3447 | D35: 2841 | E35: 3498 | F35: 4255 | G35: 3404
A36: Investment Income - Non-Operating | C36: 3447 | D36: 2841 | E36: 3498 | F36: 4255 | G36: 3404
A37: Interest Income(Exp), Net Non-Operating | C37: -- | D37: -- | E37: -- | F37: -- | G37: --
A38: Interest Inc.(Exp.),Net-Non-Op., Total | C38: 1101 | D38: 250 | E38: 812 | F38: 1522 | G38: 1182
A39: Gain (Loss) on Sale of Assets | C39: -- | D39: -- | E39: -- | F39: -- | G39: --
A40: Other, Net | C40: 98 | D40: -40 | E40: -57 | F40: -59 | G40: -251
A41: Other Non-Operating Income (Expense) | C41: 98 | D41: -40 | E41: -57 | F41: -59 | G41: -251
A42: Net Income Before Taxes | C42: 71102 | D42: 53036 | E42: 43688 | F42: 36474 | G42: 29901
...

Sheet BS
A1: Microsoft Corp | Balance Sheet 10-Feb-2022 16:56
A3: Balance Sheet
A4: Annual Standardised in Millions of U.S. Dollars
B5: 2021 | C5: 2020 | D5: 2019 | E5: 2018 | F5: 2017
A6: Earnings Quality Score | B6: 86 | C6: 94 | D6: 85 | E6: 98 | F6: 88
A7: Period End Date | B7: 30-Jun-2021 | C7: 30-Jun-2020 | D7: 30-Jun-2019 | E7: 30-Jun-2018 | F7: 30-Jun-2017
A8: Original Announcement Date | B8: 27-Jul-2021 20:42 | C8: 22-Jul-2020 20:03 | D8: 18-Jul-2019 20:04 | E8: 19-Jul-2018 20:04 | F8: 19-Jul-2018 20:04
A9: Assets ($ Millions)
A10: Cash and Short Term Investments | B10: 130334 | C10: 136527 | D10: 133819 | E10: 133650 | F10: 132881
A11: Cash & Equivalents | B11: 14224 | C11: 13576 | D11: 11356 | E11: 11946 | F11: 7663
A12: Short Term Investments | B12: 116110 | C12: 122951 | D12: 122463 | E12: 121704 | F12: 125218
A13: Accounts Receivable - Trade, Net | B13: 38043 | C13: 32011 | D13: 29524 | E13: 26481 | F13: 22431
A14: Accounts Receivable - Trade, Gross | B14: 38794 | C14: 32799 | D14: 29935 | E14: 26858 | F14: 22776
A15: Provision for Doubtful Accounts | B15: -751 | C15: -788 | D15: -411 | E15: -377 | F15: -345
A16: Total Receivables, Net | B16: 38043 | C16: 32011 | D16: 29524 | E16: 26481 | F16: 22431
A17: Total Inventory | B17: 2636 | C17: 1895 | D17: 2063 | E17: 2662 | F17: 2181
A18: Inventories - Finished Goods | B18: 1367 | C18: 1112 | D18: 1611 | E18: 1953 | F18: 1239
A19: Inventories - Work In Progress | B19: 79 | C19: 83 | D19: 53 | E19: 54 | F19: 145
A20: Inventories - Raw Materials | B20: 1190 | C20: 700 | D20: 399 | E20: 655 | F20: 797
A21: Prepaid Expenses | B21: -- | C21: -- | D21: -- | E21: -- | F21: --
A22: Other Current Assets, Total | B22: 13393 | C22: 11482 | D22: 10146 | E22: 6869 | F22: 5203
A23: Other Current Assets | B23: 13393 | C23: 11482 | D23: 10146 | E23: 6869 | F23: 5203
A24: Total Current Assets | B24: 184406 | C24: 181915 | D24: 175552 | E24: 169662 | F24: 162696
A26: Property/Plant/Equipment, Total - Gross | B26: 122154 | C26: 96101 | D26: 79186 | E26: 65369 | F26: 54468
A27: Buildings - Gross | B27: 50812 | C27: 39482 | D27: 31604 | E27: 25339 | F27: 21348
A28: Land/Improvements - Gross | B28: 3660 | C28: 1823 | D28: 1540 | E28: 1254 | F28: 1107
A29: Machinery/Equipment - Gross | B29: 51250 | C29: 41261 | D29: 33823 | E29: 27633 | F29: 21414
A30: Other Property/Plant/Equipment - Gross | B30: 16432 | C30: 13535 | D30: 12219 | E30: 11143 | F30: 10599
A31: Property/Plant/Equipment, Total - Net | B31: 70803 | C31: 52904 | D31: 43856 | E31: 36146 | F31: 30289
A32: Accumulated Depreciation, Total | B32: -51351 | C32: -43197 | D32: -35330 | E32: -29223 | F32: -24179
A33: Goodwill, Net | B33: 49711 | C33: 43351 | D33: 42026 | E33: 35683 | F33: 35122
A34: Intangibles, Net | B34: 7800 | C34: 7038 | D34: 7750 | E34: 8053 | F34: 10106
... A43: Total Assets | B43: 333779 | C43: 301311 | D43: 286556 | E43: 258848 | F43: 250312
A45: Liabilities ($ Millions)
A46: Accounts Payable | B46: 15163 | C46: 12530 | D46: 9382 | E46: 8617 | F46: 7390
A47: Payable/Accrued | B47: -- | C47: -- | D47: -- | E47: -- | F47: --
A48: Accrued Expenses | B48: 12019 | C48: 9490 | D48: 8345 | E48: 7502 | F48: 5819
A49: Notes Payable/Short Term Debt | B49: 0 | C49: 0 | D49: 0 | E49: 0 | F49: 9072
A50: Current Port. of LT Debt/Capital Leases | B50: 8863 | C50: 4289 | D50: 5833 | E50: 4174 | F50: 1162
A51: Other Current liabilities, Total | B51: 52612 | C51: 46001 | D51: 45860 | E51: 38195 | F51: 32302
...

Sheet Prices
I2: Daily Retuns (%)
C3: Dates | D3: MSFT | E3: SPX Index | F3: Volume (MSFT) | I3: MSFT | J3: SPX Index
C4: 43140 | D4: 88.18 | E4: 2619.55 | F4: 63499.1 | L4: Regression Beta (3Y Daily) | N4: =SLOPE(I5:I1047,J5:J1047) -> 1.1886839
C5: 43143 | D5: 89.13 | E5: 2656 | F5: 35720.3 | I5: =D5/D4-1 -> 0.010773418 | J5: =E5/E4-1 -> 0.013914604
C6: 43144 | D6: 89.83 | E6: 2662.94 | F6: 26407.7 | I6: =D6/D5-1 -> 0.0078536968 | J6: =E6/E5-1 -> 0.0026129518
C7: 43145 | D7: 90.81 | E7: 2698.63 | F7: 34960.9 | I7: =D7/D6-1 -> 0.010909496 | J7: =E7/E6-1 -> 0.01340248
C8: 43146 | D8: 92.66 | E8: 2731.2 | F8: 27823.9 | I8: =D8/D7-1 -> 0.020372206 | J8: =E8/E7-1 -> 0.012069087
C9: 43147 | D9: 92 | E9: 2732.22 | F9: 30596.9 | I9: =D9/D8-1 -> -0.0071228146 | J9: =E9/E8-1 -> 0.00037346221
C10: 43150 | D10: 92 | E10: 2732.22 | F10: #N/A | I10: =D10/D9-1 -> 0 | J10: =E10/E9-1 -> 0
C11: 43151 | D11: 92.72 | E11: 2716.26 | F11: 30911.7 | I11: =D11/D10-1 -> 0.007826087 | J11: =E11/E10-1 -> -0.0058414037
C12: 43152 | D12: 91.49 | E12: 2701.33 | F12: 26922.5 | I12: =D12/D11-1 -> -0.013265746 | J12: =E12/E11-1 -> -0.0054965283
C13: 43153 | D13: 91.73 | E13: 2703.96 | F13: 24392.8 | I13: =D13/D12-1 -> 0.0026232375 | J13: =E13/E12-1 -> 0.00097359449
C14: 43154 | D14: 94.06 | E14: 2747.3 | F14: 26329.2 | I14: =D14/D13-1 -> 0.025400632 | J14: =E14/E13-1 -> 0.016028344
C15: 43157 | D15: 95.42 | E15: 2779.6 | F15: 30199.8 | I15: =D15/D14-1 -> 0.014458856 | J15: =E15/E14-1 -> 0.011756998
C16: 43158 | D16: 94.2 | E16: 2744.28 | F16: 25869.1 | I16: =D16/D15-1 -> -0.01278558 | J16: =E16/E15-1 -> -0.012706864
C17: 43159 | D17: 93.77 | E17: 2713.83 | F17: 31167.3 | I17: =D17/D16-1 -> -0.0045647558 | J17: =E17/E16-1 -> -0.011095807
C18: 43160 | D18: 92.85 | E18: 2677.67 | F18: 37135.6 | I18: =D18/D17-1 -> -0.0098112403 | J18: =E18/E17-1 -> -0.013324342
C19: 43161 | D19: 93.05 | E19: 2691.25 | F19: 32830.4 | I19: =D19/D18-1 -> 0.0021540118 | J19: =E19/E18-1 -> 0.0050715734
C20: 43164 | D20: 93.64 | E20: 2720.94 | F20: 23901.6 | I20: =D20/D19-1 -> 0.0063406771 | J20: =E20/E19-1 -> 0.011032048
C21: 43165 | D21: 93.32 | E21: 2728.12 | F21: 22175.8 | I21: =D21/D20-1 -> -0.003417343 | J21: =E21/E20-1 -> 0.0026387939
C22: 43166 | D22: 93.86 | E22: 2726.8 | F22: 26716.1 | I22: =D22/D21-1 -> 0.0057865409 | J22: =E22/E21-1 -> -0.00048384968
... C38: 43188 | D38: 91.27 | E38: 2640.87 | F38: 45867.5 | I38: =D38/D37-1 -> 0.021031435 | J38: =E38/E37-1 -> 0.013769674
C39: 43189 | D39: 91.27 | E39: 2640.87 | F39: #N/A | I39: =D39/D38-1 -> 0 | J39: =E39/E38-1 -> 0
C40: 43192 | D40: 88.52 | E40: 2581.88 | F40: 48515.4 | I40: =D40/D39-1 -> -0.030130382 | J40: =E40/E39-1 -> -0.022337336
C41: 43193 | D41: 89.71 | E41: 2614.45 | F41: 37213.8 | I41: =D41/D40-1 -> 0.01344329 | J41: =E41/E40-1 -> 0.012614839
C42: 43194 | D42: 92.33 | E42: 2644.69 | F42: 35560 | I42: =D42/D41-1 -> 0.029205217 | J42: =E42/E41-1 -> 0.011566486
C43: 43195 | D43: 92.38 | E43: 2662.84 | F43: 29771.9 | I43: =D43/D42-1 -> 0.0005415358 | J43: =E43/E42-1 -> 0.0068628081
C44: 43196 | D44: 90.23 | E44: 2604.47 | F44: 38026 | I44: =D44/D43-1 -> -0.023273436 | J44: =E44/E43-1 -> -0.021920205
C45: 43199 | D45: 90.77 | E45: 2613.16 | F45: 31533.9 | I45: =D45/D44-1 -> 0.0059847058 | J45: =E45/E44-1 -> 0.0033365714
C46: 43200 | D46: 92.88 | E46: 2656.87 | F46: 26939.9 | I46: =D46/D45-1 -> 0.023245566 | J46: =E46/E45-1 -> 0.016726875
C47: 43201 | D47: 91.86 | E47: 2642.19 | F47: 24872.1 | I47: =D47/D46-1 -> -0.010981912 | J47: =E47/E46-1 -> -0.0055252986
C48: 43202 | D48: 93.58 | E48: 2663.99 | F48: 26758.9 | I48: =D48/D47-1 -> 0.018724145 | J48: =E48/E47-1 -> 0.0082507314
C49: 43203 | D49: 93.08 | E49: 2656.3 | F49: 23346.1 | I49: =D49/D48-1 -> -0.005343022 | J49: =E49/E48-1 -> -0.0028866475
C50: 43206 | D50: 94.17 | E50: 2677.84 | F50: 20288.1 | I50: =D50/D49-1 -> 0.011710357 | J50: =E50/E49-1 -> 0.0081090238
C51: 43207 | D51: 96.07 | E51: 2706.39 | F51: 26771 | I51: =D51/D50-1 -> 0.020176277 | J51: =E51/E50-1 -> 0.010661578
... C79: 43245 | D79: 98.36 | E79: 2721.33 | F79: 18363.9 | I79: =D79/D78-1 -> 0.00050859526 | J79: =E79/E78-1 -> -0.0023572455
C80: 43248 | D80: 98.36 | E80: 2721.33 | F80: #N/A | I80: =D80/D79-1 -> 0 | J80: =E80/E79-1 -> 0
C81: 43249 | D81: 98.01 | E81: 2689.86 | F81: 28671 | I81: =D81/D80-1 -> -0.0035583571 | J81: =E81/E80-1 -> -0.011564198
C82: 43250 | D82: 98.95 | E82: 2724.01 | F82: 22158.5 | I82: =D82/D81-1 -> 0.0095908581 | J82: =E82/E81-1 -> 0.012695828
C83: 43251 | D83: 98.84 | E83: 2705.27 | F83: 34140.9 | I83: =D83/D82-1 -> -0.0011116726 | J83: =E83/E82-1 -> -0.0068795636
...

Sheet Questions
E1: Total time to complete the test: 90min
D2: 1 | E2: From the statements provided (Tabs: "IS" and "BS") calculate the following. (Use excel linkings to show calculations and average data over the period for BS)
F4: FY2021 | G4: FY2020 | H4: FY2019 | I4: FY2018
E5: Asset Turnover | F5: =IS!C9/((BS!C43+BS!B43)/2) -> 0.529336 | G5: =IS!D9/((BS!D43+BS!C43)/2) -> 0.48655563 | H5: =IS!E9/((BS!E43+BS!D43)/2) -> 0.4614671 | I5: =IS!F9/((BS!F43+BS!E43)/2) -> 0.43349831
E6: Quick Ratio | F6: =(BS!B10+BS!B13)/BS!B56 -> 1.8991958 | G6: =(BS!C10+BS!C13)/BS!C56 -> 2.3307703 | H6: =(BS!D10+BS!D13)/BS!D56 -> 2.3529674 | I6: =(BS!E10+BS!E13)/BS!E56 -> 2.7378437
E7: Times Interest Earned | F7: =IS!C32/ABS(IS!C33+IS!C112) -> 35.664796 | G7: =IS!D32/ABS(IS!D33+IS!D112) -> 23.426164 | H7: =IS!E32/ABS(IS!E33+IS!E112) -> 17.602706 | I7: =IS!F32/ABS(IS!F33+IS!F112) -> 13.686865
E8: Cash Cycle | F8: =F14+F15-F16 -> -4.8681591 | G8: =G14+G15-G16 -> 7.4142276 | H8: =H14+H15-H16 -> 24.764067 | I8: =I14+I15-I16 -> 27.761647
E10: Inventory Turnover | F10: =IS!C13/((BS!B17+BS!C17)/2) -> 23.055396 | G10: =IS!D13/((BS!C17+BS!D17)/2) -> 23.283477 | H10: =IS!E13/((BS!D17+BS!E17)/2) -> 18.162963 | I10: =IS!F13/((BS!E17+BS!F17)/2) -> 15.83853
E11: Receivables Turnover | F11: =IS!C9/((BS!B16+BS!C16)/2) -> 4.7988123 | G11: =IS!D9/((BS!C16+BS!D16)/2) -> 4.648249 | H11: =IS!E9/((BS!D16+BS!E16)/2) -> 4.4939916 | I11: =IS!F9/((BS!E16+BS!F16)/2) -> 4.512594
E12: Payable Turnover | F12: =IS!C13/((BS!B46+BS!C46)/2) -> 3.7722168 | G12: =IS!D13/((BS!C46+BS!D46)/2) -> 4.205732 | H12: =IS!E13/((BS!D46+BS!E46)/2) -> 4.7680427 | I12: =IS!F13/((BS!E46+BS!F46)/2) -> 4.7920285
E14: Days of Sale O/s | F14: =365/F10 -> 15.831435 | G14: =365/G10 -> 15.676353 | H14: =365/H10 -> 20.09584 | I14: =365/I10 -> 23.045068
E15: Days of Inv on Hand | F15: =365/F11 -> 76.060486 | G15: =365/G11 -> 78.524193 | H15: =365/H11 -> 81.219555 | I15: =365/I11 -> 80.884741
E16: Days of Payable | F16: =365/F12 -> 96.76008 | G16: =365/G12 -> 86.786319 | H16: =365/H12 -> 76.551328 | I16: =365/I12 -> 76.168162
D18: 2 | E18: Calculate 3 year daily beta using the prices provided in tab "Prices" . Show the required working in "Prices" tab after Column H.
D20: 3 | E20: Populate a Price Line Chart (in single chart) for both Microsoft & S&P 500 Index using price data provided in "Prices" tab. Plot the same in "Prices" tab.
D22: 4 | E22: Populate a Price Line Chart and volume bar chart (in single chart) using price data provided. Plot the same in "Prices" tab.
D24: 5 | E24: Calculate YTD, QTD, MTD, WTD price performances (returns) for Microsoft based on the date mentioned in Cell E18, please make the calculations dynamic using excel. Use data in "Prices" tab.
E26: 44507 | F26: YTD | G26: QTD | H26: MTD | I26: WTD
E27: Date | F27: =Prices!C759 -> 44197 | G27: =Prices!C954 -> 44470 | H27: =Prices!C975 -> 44501 | I27: =Prices!C975 -> 44501
E28: Returns | F28: =(Prices!$D$979-Prices!D759)/Prices!D759 -> 0.51092573 | G28: =(Prices!D979-Prices!D956)/Prices!D954 -> 0.1636115 | H28: =(Prices!D979-Prices!D975)/Prices!D975 -> 0.020311498 | I28: =(Prices!D979-Prices!D975)/Prices!D975 -> 0.020311498
D30: 6 | E30: Concatenate the following two words with a space in between as a delimiter
E31: Robert | F31: Smith
E32: Answer | F32: =CONCATENATE(E31," ",F31) -> Robert Smith
D34: 7 | E34: Transpose the below data in space provided
K35: Please use excel function to do this
E36: Dates | F36: MSFT.O | G36: .SPX | J36: Answer: | K36: {=TRANSPOSE(E36:E45)} -> Dates | L36: 43140 | M36: 43143 | N36: 43144 | O36: 43145 | P36: 43146 | Q36: 43147 | R36: 43150 | S36: 43151 | T36: 43152
E37: 43140 | F37: 88.18 | G37: 2619.55 | K37: {=TRANSPOSE(F36:F45)} -> MSFT.O | L37: 88.18 | M37: 89.13 | N37: 89.83 | O37: 90.81 | P37: 92.66 | Q37: 92 | R37: 92 | S37: 92.72 | T37: 91.49
E38: 43143 | F38: 89.13 | G38: 2656 | K38: {=TRANSPOSE(G36:G45)} -> .SPX | L38: 2619.55 | M38: 2656 | N38: 2662.94 | O38: 2698.63 | P38: 2731.2 | Q38: 2732.22 | R38: 2732.22 | S38: 2716.26 | T38: 2701.33
E39: 43144 | F39: 89.83 | G39: 2662.94
E40: 43145 | F40: 90.81 | G40: 2698.63
E41: 43146 | F41: 92.66 | G41: 2731.2
E42: 43147 | F42: 92 | G42: 2732.22
E43: 43150 | F43: 92 | G43: 2732.22
E44: 43151 | F44: 92.72 | G44: 2716.26
E45: 43152 | F45: 91.49 | G45: 2701.33
D47: 8 | E47: Please use the below assumptions to answer the questions asked below
E48: Values for subject firm | H48: Values for peer group
E49: 5-year EPS growth rate | F49: 0.08 | H49: Median P/E | I49: 9
E50: Consensus EPS forecast | F50: 4.5 | H50: Median PEG | I50: 1.6
E51: Current stock price | F51: 28
...
